Workbook

Sheet CTRA. GUADALMAR
B1: GR 535.2.2 MEJORA CARRETERA GUADALMAR – REVISIÓN AUDITADA 07/04/2026
B2: NIVEL I: volúmenes corregidos con mediciones auxiliares confirmadas. Celdas VERDE = modificadas. Ver col J para detalle.
B4: MEJORA CARRETERA DE GUADALMAR
B6: Partidas de retirada de tierras procedentes de la excavacion, RCD´s NIVEL I
B7: (volumen de tierras y petreos no contaminados)
C9: RCD: Volumen de tierras y pétrea no contaminados
E10: Volumen (m³) | F10: ct x ct | G10: tn
C11: Excavacion Desbroce | E11: 4204.09 | F11: 1.5 x 1.15 | G11: =E9*1.5*1.15 -> 0 | I11: MDT001(LM-1.02) | J11: [AUD 07/04/2026] Desbroce: ant.6970→4204.09 m³ [Trazado.xlsx suma 5 tramos]
C12: Saneo y desmonte trazado (se deduce suelo adecuado a utilizar en obra) | E12: 26391.19 | F12: 1.5 x 1.15 | G12: =E10*1.5*1.15 -> #VALUE! | I12: EXCADESMONTE+EXCASANRELL-RELLENOTERRA (LM-1.02) | J12: [AUD 07/04/2026] Desmonte: ant.21000→26391.19 m³ [Trazado.xlsx suma 5 tramos]
C13: Total Vol. Tierras no contaminadas | E13: =E9+E10 -> #VALUE! | G13: =E11*1.5*1.15 -> 7252.0552 | J13: [AUD] Total Nivel I: ant.33280→=E9+E10 (30595.28 m³). Nota: 33280≠6970+21000; valor heredado era inconsistente.
B16: Resto de partidas que generan residuos de forma indirecta al ejecutar la unidad de obra, RCD´s NIVEL II
B17: Estimación de residuos totales por parámetros estimativos
C19: Estimación de residuos totales en la ejecución de las obras
C20: Superficie construida (m2) | E20: Vol. de Residuos | F20: D. tipo (t/m³) | G20: Toneladas
C21: 33032 | E21: sup. X 0,20 | F21: 1.5 | G21: =C19*0.2*F19 -> #VALUE! | I21: AREA DE CIVIL3D | J21: [AUD 07/04/2026] 36.055 m² de Civil 3D. PENDIENTE verificar con plano de planta definitivo.
B23: Estimacion del peso de Residuos por tipo (ratios obtenidos del colegio oficial de arquitectos de Sevilla)
C24: Estimacion del peso de Residuos por tipo
C25: Evaluación teórica del peso por tipología de RCD | E25: % en Peso | F25: Tn de cada tipo de RCD | G25: m³ de cada tipo de RCD
C26: RCD: Naturaleza no pétrea
C27: Asfalto | E27: 5 | F27: =(G19*E25)/100 -> #VALUE! | G27: =F25/2.55 -> #VALUE!
C28: Madera | E28: 4 | F28: =(G19*E26)/100 -> 0 | G28: =F26/4 -> 0
C29: Metales | E29: 2.5 | F29: =(G19*E27)/100 -> 0 | G29: =F27/7.5 -> #VALUE!
C30: Papel | E30: 0.3 | F30: =(G19*E28)/100 -> 0 | G30: =F28/1.1 -> 0
C31: Plastico | E31: 1.5 | F31: =(G19*E29)/100 -> 0 | G31: =F29/1.4 -> 0
C32: Vidrio | E32: 0.5 | F32: =(G19*E30)/100 -> 0 | G32: =F30/2.5 -> 0
C33: Yeso
C34: Total Naturaleza no pétrea | E34: =SUM(E25:E31) -> 13.3 | F34: =SUM(F25:F31) -> #VALUE! | G34: =SUM(G25:G31) -> #VALUE!
C35: RCD: Naturaleza pétrea
C36: Arena, grava y otros aridos | E36: 4 | F36: =(G19*E34)/100 -> 0 | G36: =F34/1.5 -> #VALUE!
C37: Hormigon | E37: 12 | F37: =(G19*E35)/100 -> 0 | G37: =F35/2.4 -> 0
C38: Ladrillos, tejas y materiales cerámicos | E38: 15 | F38: =(G19*E36)/100 -> 0 | G38: =F36/1.35 -> 0
C39: Piedra
C40: Total Naturaleza pétrea | E40: =SUM(E34:E37) -> 29.3 | F40: =SUM(F34:F37) -> #VALUE! | G40: =SUM(G34:G37) -> #VALUE!
C41: RCD: Potencialmente Peligrosos
C42: Basura | E42: 1.5 | F42: =(G19*E40)/100 -> 0 | G42: =F40/1.8 -> #VALUE!
C43: Peligrosos y otros | E43: 0.5 | F43: =(G19*E41)/100 -> 0 | G43: =F41/1.8 -> 0
C44: Total RCD Potencialmente Peligrosos | E44: =SUM(E40:E41) -> 29.3 | F44: =SUM(F40:F41) -> #VALUE! | G44: =SUM(G40:G41) -> #VALUE!
B47: Partidas de demolición y desmontaje (según mediciones proyecto), RCD's NIVEL II
B48: Estimación de residuos totales por parámetros estimativos
C50: Estimación de residuos totales en la demolición de edificaciones y elementos existentes
...

Sheet TABLA LER-DESTINOS
B3: Material según Lista Europea de Residuos (LER), conforme a Orden MAM 304/2002 y Decisión de la Comisión 2014/955/UE, de 18 de diciembre de 2014 | C3: Código LER | D3: Tratamiento | E3: Destino | F3: Peso | G3: Volumen
F4: (t) | G4: (m³)
B5: RCD de Nivel I
B6: 1 Tierras y pétreos de la excavación
B7: Tierra y piedras distintas de las especificadas en el código 17 05 03. | C7: 17 05 04 | D7: Sin tratamiento específico | E7: Restauración / Vertedero | F7: ='CTRA. GUADALMAR'!G11 -> 0 | G7: =F7/(1.5*1.15) -> 0
B8: RCD de Nivel II
B9: RCD de naturaleza no pétrea
B10: 1 Asfalto
B11: Mezclas bituminosas distintas de las especificadas en el código 17 03 01. | C11: 17 03 02 | D11: Reciclado | E11: Planta reciclaje RCD | F11: ='CTRA. GUADALMAR'!F25+'CTRA. GUADALMAR'!F64 -> #VALUE! | G11: ='CTRA. GUADALMAR'!G25+'CTRA. GUADALMAR'!G64 -> #VALUE!
B12: 2 Madera
B13: Madera. | C13: 17 02 01 | D13: Reciclado | E13: Gestor autorizado RNPs | F13: ='CTRA. GUADALMAR'!F66+'CTRA. GUADALMAR'!F67+'CTRA. GUADALMAR'!F26 -> 0 | G13: ='CTRA. GUADALMAR'!G26+'CTRA. GUADALMAR'!G66+'CTRA. GUADALMAR'!G67 -> 0
B14: 3 Metales (incluidas sus aleaciones)
B15: Hierro y acero. | C15: 17 04 05 | D15: Reciclado | E15: Gestor autorizado RNPs | F15: ='CTRA. GUADALMAR'!F27+'CTRA. GUADALMAR'!F69+'CTRA. GUADALMAR'!F70+'CTRA. GUADALMAR'!F71 -> #VALUE! | G15: ='CTRA. GUADALMAR'!G27+'CTRA. GUADALMAR'!G69+'CTRA. GUADALMAR'!G70+'CTRA. GUADALMAR'!G71 -> #VALUE!
B16: 4 Papel y cartón
B17: Envases de papel y cartón. | C17: 15 01 01 | D17: Reciclado | E17: Gestor autorizado RNPs | F17: ='CTRA. GUADALMAR'!F28 -> 0 | G17: ='CTRA. GUADALMAR'!G28+'CTRA. GUADALMAR'!G73 -> 0.138
B18: 5 Plástico
B19: Plástico. | C19: 17 02 03 | D19: Reciclado | E19: Gestor autorizado RNPs | F19: ='CTRA. GUADALMAR'!F29+'CTRA. GUADALMAR'!F75+'CTRA. GUADALMAR'!F76+'CTRA. GUADALMAR'!F77 -> #VALUE! | G19: ='CTRA. GUADALMAR'!G29+'CTRA. GUADALMAR'!G75+'CTRA. GUADALMAR'!G76+'CTRA. GUADALMAR'!G77 -> #VALUE!
B20: 6 Vidrio
B21: Vidrio. | C21: 17 02 02 | D21: Reciclado | E21: Gestor autorizado RNPs | F21: ='CTRA. GUADALMAR'!F30+'CTRA. GUADALMAR'!F78 -> #VALUE! | G21: ='CTRA. GUADALMAR'!G30+'CTRA. GUADALMAR'!G78 -> 0
B22: 7 Yeso
B23: Materiales de construcción a base de yeso distintos de los especificados en el código 17 08 01. | C23: 17 08 02 | D23: Depósito / Tratamiento | E23: Gestor autorizado RNPs | F23: ='CTRA. GUADALMAR'!F31+'CTRA. GUADALMAR'!F78 -> #VALUE! | G23: ='CTRA. GUADALMAR'!G31+'CTRA. GUADALMAR'!G80 -> #VALUE!
B24: 8 Residuos mezclados
B25: Residuos mezclados de construcción y demolición distintos de los especificados en los códigos 17 09 01, 17 09 02 y 17 09 03. | C25: 17 09 04 | D25: Reciclado | E25: Gestor autorizado RNPs | F25: ='CTRA. GUADALMAR'!F40+'CTRA. GUADALMAR'!F95 -> #VALUE! | G25: ='CTRA. GUADALMAR'!G40+'CTRA. GUADALMAR'!G95 -> #VALUE!
B26: Materiales de aislamiento distintos de los especificados en los códigos 17 06 01 y 17 06 03. | C26: 17 06 04 | D26: Depósito / Tratamiento | E26: Gestor autorizado RNPs | F26: ='CTRA. GUADALMAR'!F96 -> 0 | G26: ='CTRA. GUADALMAR'!G96 -> 0
B27: Residuos biodegradables. | C27: 20 02 01 | D27: Reciclado / Vertedero | E27: Planta reciclaje RSU | F27: 1.8 | G27: 1
B28: Residuos de la limpieza viaria. | C28: 20 03 03 | D28: Reciclado / Vertedero | E28: Planta reciclaje RSU | F28: 0.2 | G28: 0.1
B29: RCD de naturaleza pétrea
B30: 1 Arena, grava y otros áridos
B31: Residuos de grava y rocas trituradas distintos de los mencionados en el código 01 04 07. | C31: 01 04 08 | D31: Reciclado | E31: Planta reciclaje RCD | F31: ='CTRA. GUADALMAR'!F34+'CTRA. GUADALMAR'!F84 -> #VALUE! | G31: ='CTRA. GUADALMAR'!G34+'CTRA. GUADALMAR'!G84 -> #VALUE!
B32: Residuos de arena y arcillas. | C32: 01 04 09 | D32: Reciclado | E32: Planta reciclaje RCD | F32: 0 | G32: 0
B33: 2 Hormigón
B34: Hormigón (hormigones, morteros y prefabricados). | C34: 17 01 01 | D34: Reciclado / Vertedero | E34: Planta reciclaje RCD | F34: ='CTRA. GUADALMAR'!F35+'CTRA. GUADALMAR'!F86+'CTRA. GUADALMAR'!F87+'CTRA. GUADALMAR'!F88 -> #VALUE! | G34: ='CTRA. GUADALMAR'!G35+'CTRA. GUADALMAR'!G86+'CTRA. GUADALMAR'!G87+'CTRA. GUADALMAR'!G88+'CTRA. GUADALMAR'!G89 -> #VALUE!
B35: 3 Ladrillos, tejas y materiales cerámicos
B36: Mezclas de hormigón, ladrillos, tejas y materiales cerámicos distintas de las especificadas en el código 17 01 06. | C36: 17 01 07 | D36: Reciclado / Vertedero | E36: Planta reciclaje RCD | F36: ='CTRA. GUADALMAR'!F36+'CTRA. GUADALMAR'!F91 -> 7.705 | G36: ='CTRA. GUADALMAR'!G36+'CTRA. GUADALMAR'!G91 -> #VALUE!
B37: 4 Piedra
B38: Mezclas de piedras y materiales rocosos distintas de las especificadas | C38: 17 05 04 | D38: Reciclado / Vertedero | E38: Planta reciclaje RCD | F38: ='CTRA. GUADALMAR'!F37+'CTRA. GUADALMAR'!F92 -> 0 | G38: ='CTRA. GUADALMAR'!G37+'CTRA. GUADALMAR'!G92 -> 0
