Workbook

Sheet CTRA. GUADALMAR
B2: MEJORA CARRETERA DE GUADALMAR
B4: Partidas de retirada de tierras procedentes de la excavacion, RCD´s NIVEL I
B5: (volumen de tierras y petreos no contaminados)
C7: RCD: Volumen de tierras y pétrea no contaminados
E8: Volumen (m³) | F8: ct x ct | G8: tn
C9: Excavacion Desbroce | E9: 4204.09 | F9: 1.5 x 1.15 | G9: =(E9*1.15)*1.5 -> 12023.25 | I9: MDT001(LM-1.02)
C10: Saneo y desmonte trazado (se deduce suelo adecuado a utilizar en obra) | E10: 21000 | F10: 1.5 x 1.15 | G10: =(E10*1.15)*1.5 -> 36225 | I10: EXCADESMONTE+EXCASANRELL-RELLENOTERRA (LM-1.02)
C11: Total Vol. Tierras no contaminadas | E11: 33280 | G11: =SUM(G9:G10) -> 48248.25
B14: Resto de partidas que generan residuos de forma indirecta al ejecutar la unidad de obra, RCD´s NIVEL II
B15: Estimacion de Residuos totales por parámetros estimativos
C17: Estimacion Residuos Total en la ejecucion de las Obras
C18: Superficie construida (m2) | E18: Vol. de Residuos | F18: D. tipo (t/m³) | G18: Toneladas
C19: 33032 | E19: sup. X 0,20 | F19: 1.5 | G19: =C19*0.2*F19 -> 9909.6 | I19: AREA DE CIVIL3D
B21: Estimacion del peso de Residuos por tipo (ratios obtenidos del colegio oficial de arquitectos de Sevilla)
C22: Estimacion del peso de Residuos por tipo
C23: Evaluacon teórica del peso por tipologia de RCD | E23: % en Peso | F23: Tn de cada tipo de RCD | G23: m³ de cada tipo de RCD
C24: RCD: Naturaleza no pétrea
C25: Asfalto | E25: 5 | F25: =(G19*E25)/100 -> 495.48 | G25: =F25/2.3 -> 215.42609
C26: Madera | E26: 4 | F26: =(G19*E26)/100 -> 396.384 | G26: =F26/0.6 -> 660.64
C27: Metales | E27: 2.5 | F27: =(G19*E27)/100 -> 247.74 | G27: =F27/7.5 -> 33.032
C28: Papel | E28: 0.3 | F28: =(G19*E28)/100 -> 29.7288 | G28: =F28/1.1 -> 27.026182
C29: Plastico | E29: 1.5 | F29: =(G19*E29)/100 -> 148.644 | G29: =F29/1.4 -> 106.17429
C30: Vidrio | E30: 0.5 | F30: =(G19*E30)/100 -> 49.548 | G30: =F30/2.5 -> 19.8192
C31: Yeso | E31: 0.2 | F31: =(G19*E31)/100 -> 19.8192 | G31: =F31/1.5 -> 13.2128
C32: Total Naturaleza no pétrea | E32: =SUM(E25:E31) -> 14 | F32: =SUM(F25:F31) -> 1387.344 | G32: =SUM(G25:G31) -> 1075.3306
C33: RCD: Naturaleza pétrea
C34: Arena, grava y otros aridos | E34: 4 | F34: =(G19*E34)/100 -> 396.384 | G34: =F34/1.5 -> 264.256
C35: Hormigon | E35: 12 | F35: =(G19*E35)/100 -> 1189.152 | G35: =F35/2.4 -> 495.48
C36: Ladrillos, azulejos y otros ceramicos | E36: 15 | F36: =(G19*E36)/100 -> 1486.44 | G36: =F36/1.35 -> 1101.0667
C37: Piedra | E37: 5 | F37: =(G19*E37)/100 -> 495.48 | G37: =F37/2.5 -> 198.192
C38: Total Naturaleza pétrea | E38: =SUM(E34:E37) -> 36 | F38: =SUM(F34:F37) -> 3567.456 | G38: =SUM(G34:G37) -> 2058.9947
C39: RCD: Potencialmente Peligrosos
C40: Basura | E40: 7 | F40: =(G19*E40)/100 -> 693.672 | G40: =F40/0.6 -> 1156.12
C41: Peligrosos y otros | E41: 4 | F41: =(G19*E41)/100 -> 396.384 | G41: =F41/1.1 -> 360.34909
C42: Total Potencialmente Peligoroso | E42: =SUM(E40:E41) -> 11 | F42: =SUM(F40:F41) -> 1090.056 | G42: =SUM(G40:G41) -> 1516.4691
B45: Partidas de Demolicion y Desmontaje (según mediciones proyecto), RCD´s NIVEL II
B46: Estimacion de Residuos totales por parámetros estimativos
C48: Estimacion Residuos Total en la demolicion de Edificacaciones existentes
C49: Descripción | E49: medición (PU) | G49: paso unidad
C50: (1) Demolicion fabrica de ladrillo | E50: 207 | F50: m3 | G50: =E50/0.3 -> 690 | H50: m2 | I50: 01EMM12315486 (LM-1.01)
...

Sheet Hoja2
B3: Material según "Orden MAM 304/2002. Operaciones de valorización y eliminación de residuos y Lista europea de residuos" | C3: Código LER | D3: Tratamiento | E3: Destino | F3: Peso | G3: Volumen
F4: (t) | G4: (m³)
B5: RCD de Nivel I
B6: 1 Tierras y pétreos de la excavación
B7: Tierra y piedras distintas de las especificadas en el código 17 05 03. | C7: 17 05 04 | D7: Sin tratamiento específico | E7: Restauración / Vertedero | F7: ='CTRA. GUADALMAR'!G11 -> 48248.25 | G7: =F7/(1.5*1.15) -> 27970
B8: RCD de Nivel II
B9: RCD de naturaleza no pétrea
B10: 1 Asfalto
B11: Mezclas bituminosas distintas de las especificadas en el código 17 03 01. | C11: 17 03 02 | D11: Reciclado | E11: Planta reciclaje RCD | F11: ='CTRA. GUADALMAR'!F25+'CTRA. GUADALMAR'!F64 -> 1476.3877 | G11: ='CTRA. GUADALMAR'!G25+'CTRA. GUADALMAR'!G64 -> 600.09577
B12: 2 Madera
B13: Madera. | C13: 17 02 01 | D13: Reciclado | E13: Gestor autorizado RNPs | F13: ='CTRA. GUADALMAR'!F66+'CTRA. GUADALMAR'!F67+'CTRA. GUADALMAR'!F26 -> 396.917 | G13: ='CTRA. GUADALMAR'!G26+'CTRA. GUADALMAR'!G66+'CTRA. GUADALMAR'!G67 -> 661.12455
B14: 3 Metales (incluidas sus aleaciones)
B15: Hierro y acero. | C15: 17 04 05 | D15: Reciclado | E15: Gestor autorizado RNPs | F15: ='CTRA. GUADALMAR'!F27+'CTRA. GUADALMAR'!F69+'CTRA. GUADALMAR'!F70+'CTRA. GUADALMAR'!F71 -> 250.04792 | G15: ='CTRA. GUADALMAR'!G27+'CTRA. GUADALMAR'!G69+'CTRA. GUADALMAR'!G70+'CTRA. GUADALMAR'!G71 -> 33.339722
B16: 4 Papel y cartón
B17: Envases de papel y cartón. | C17: 15 01 01 | D17: Reciclado | E17: Gestor autorizado RNPs | F17: ='CTRA. GUADALMAR'!F28 -> 29.7288 | G17: ='CTRA. GUADALMAR'!G28+'CTRA. GUADALMAR'!G73 -> 27.787909
B18: 5 Plástico
B19: Plástico. | C19: 17 02 03 | D19: Reciclado | E19: Gestor autorizado RNPs | F19: ='CTRA. GUADALMAR'!F29+'CTRA. GUADALMAR'!F75+'CTRA. GUADALMAR'!F76+'CTRA. GUADALMAR'!F77 -> 149.49508 | G19: ='CTRA. GUADALMAR'!G29+'CTRA. GUADALMAR'!G75+'CTRA. GUADALMAR'!G76+'CTRA. GUADALMAR'!G77+'CTRA. GUADALMAR'!G78 -> 106.7822
B20: 6 Vidrio
B21: Residuos de vidrio distintos de los especificados en el código 10 11 11 | C21: 17 02 02 | D21: Reciclado | E21: Gestor autorizado RNPs | F21: ='CTRA. GUADALMAR'!F30+'CTRA. GUADALMAR'!F78 -> 49.548 | G21: ='CTRA. GUADALMAR'!G30+'CTRA. GUADALMAR'!G78 -> 19.8192
B22: 7 Yeso
B23: Materiales de construcción a base de yeso | C23: 17 08 02 | D23: Depósito / Tratamiento | E23: Gestor autorizado RNPs | F23: ='CTRA. GUADALMAR'!F31+'CTRA. GUADALMAR'!F78 -> 19.8192 | G23: ='CTRA. GUADALMAR'!G31+'CTRA. GUADALMAR'!G80 -> 14.8088
B24: 6 Basuras
B25: Materiales de aislamiento distintos de los especificados en los códigos 17 06 01 y 17 06 03. | C25: 17 06 04 | D25: Reciclado | E25: Gestor autorizado RNPs | F25: ='CTRA. GUADALMAR'!F40+'CTRA. GUADALMAR'!F95 -> 748.872 | G25: ='CTRA. GUADALMAR'!G40+'CTRA. GUADALMAR'!G95 -> 1186.7867
B26: Residuos mezclados de construcción y demolición distintos de los especificados en los códigos 17 09 01, 17 09 02 y 17 09 03. | C26: 17 09 04 | D26: Depósito / Tratamiento | E26: Gestor autorizado RPs
B27: Residuos biodegradables. | C27: 20 02 01 | D27: Reciclado / Vertedero | E27: Planta reciclaje RSU | F27: 1.8 | G27: 1
B28: Residuos de la limpieza viaria. | C28: 20 03 03 | D28: Reciclado / Vertedero | E28: Planta reciclaje RSU | F28: 0.2 | G28: 0.1
B29: RCD de naturaleza pétrea
B30: 1 Arena, grava y otros áridos
B31: Residuos de grava y rocas trituradas distintos de los mencionados en el código 01 04 07. | C31: 01 04 08 | D31: Reciclado | E31: Planta reciclaje RCD | F31: ='CTRA. GUADALMAR'!F34+'CTRA. GUADALMAR'!F84 -> 1389.894 | G31: ='CTRA. GUADALMAR'!G34+'CTRA. GUADALMAR'!G84 -> 926.596
B32: Residuos de arena y arcillas. | C32: 01 04 09 | D32: Reciclado | E32: Planta reciclaje RCD | F32: " | G32: "
B33: 2 Hormigón
B34: Hormigón (hormigones, morteros y prefabricados). | C34: 17 01 01 | D34: Reciclado / Vertedero | E34: Planta reciclaje RCD | F34: ='CTRA. GUADALMAR'!F35+'CTRA. GUADALMAR'!F86+'CTRA. GUADALMAR'!F87+'CTRA. GUADALMAR'!F88 -> 1426.1157 | G34: ='CTRA. GUADALMAR'!G35+'CTRA. GUADALMAR'!G86+'CTRA. GUADALMAR'!G87+'CTRA. GUADALMAR'!G88+'CTRA. GUADALMAR'!G89 -> 603.79821
B35: 3 Ladrillos, tejas y materiales cerámicos
B36: Mezclas de hormigón, ladrillos, tejas y materiales cerámicos distintas de las especificadas en el código 17 01 06. | C36: 17 01 07 | D36: Reciclado / Vertedero | E36: Planta reciclaje RCD | F36: ='CTRA. GUADALMAR'!F36+'CTRA. GUADALMAR'!F91 -> 1546.677 | G36: ='CTRA. GUADALMAR'!G36+'CTRA. GUADALMAR'!G91 -> 1145.6867
B37: 4 Piedra
B38: Mezclas de piedras y materiales rocosos distintas de las especificadas | C38: 17 05 08 | D38: Reciclado / Vertedero | E38: Planta reciclaje RCD | F38: ='CTRA. GUADALMAR'!F37+'CTRA. GUADALMAR'!F92 -> 495.48 | G38: ='CTRA. GUADALMAR'!G37+'CTRA. GUADALMAR'!G92 -> 198.192
