Workbook

Sheet Sección 1.1
C2: SECCIÓN 1.1
C4: SITUACIÓN DE PROYECTO | D4: ='Sección 1.1'!$F$27 -> B1
C5: CLASE DE ALUMBRADO | D5: ='Sección 1.1'!$F$28 -> ME2
C6: VALOR DE EFICIENCIA ENERGÉTICA = | D6: =('Sección 1.1'!F19*'Sección 1.1'!F20)/'Sección 1.1'!F21 -> 48.517857
C7: VALOR DE EFICIENCIA ENERGÉTICA MÍNIMA = | D7: =IF('Sección 1.1'!F29="v",'Sección 1.1'!H20,'Sección 1.1'!I20) -> 32.2
C8: EFICIENCIA>EFICIENCIA MÍNIMA | D8: =IF(D7<=D6,"CUMPLE","NO CUMPLE") -> CUMPLE
C9: EFICIENCIA ENERGÉTICA DE REFERENCIA | D9: =IF('Sección 1.1'!F29="v",'Sección 1.1'!K20,'Sección 1.1'!L20) -> 40.8
C10: INDICE DE EFICIENCIA ENERGÉTICA = | D10: =D6/D9 -> 1.1891632
C11: CLASIFICACIÓN ENERGÉTICA DE LA INSTALACIÓN = | D11: ='Sección 1.1'!N20 -> A
C12: FACTOR DE UTILIZACIÓN = | D12: =D6/(F25*F24) -> 0.391875
C13: POTENCIA UNITARIA<POTENCIA UNITARIA MÁXIMA | D13: =IF(F30<=H24,"CUMPLE","NO CUMPLE") -> CUMPLE
C15: CALCULOS
C17: Dato | D17: Referencia | E17: Ud | F17: Valor
H18: EFICIENCIA MÍNIMA | K18: EFICIENCIA REFERENCIA | N18: CALIFICACIÓN ENERGÉTICA
C19: Superficie | D19: S | E19: m2 | F19: =19*16.5 -> 313.5 | H19: Vial | I19: Camino | K19: Vial | L19: Camino
C20: Iluminancia Media | D20: Em | E20: lux | F20: 13 | H20: =IF(F20>C41,IF(F20>C40,IF(F20>C39,IF(F20>C38,IF(F20>C37,IF(F20>C36,D36,D36+((F20-C36)*(D37-D36)/(C37-C36))),D37+((F20-C37)*(D38-D37)/(C38-C37))),D38+((F20-C38)*(D39-D38)/(C39-C38))),D39+((F20-C39)*(D40-D39)/(C40-C39))),D40+((F20-C40)*(D41-D40)/(C41-C40))),D41) -> 32.2 | I20: =IF(F20>C51,IF(F20>C50,IF(F20>C49,IF(F20>C48,IF(F20>C47,D47,D47+((F20-C47)*(D48-D47)/(C48-C47))),D48+((F20-C48)*(D49-D48)/(C49-C48))),D49+((F20-C49)*(D50-D49)/(C50-C49))),D50+((F20-C50)*(D51-D50)/(C51-C50))),D51) -> 16.6 | K20: =IF(F20>I41,IF(F20>I40,IF(F20>I39,IF(F20>I38,IF(F20>I37,IF(F20>I36,J36,J36+((F20-I36)*(J37-J36)/(I37-I36))),J37+((F20-I37)*(J38-J37)/(I38-I37))),J38+((F20-I38)*(J39-J38)/(I39-I38))),J39+((F20-I39)*(J40-J39)/(I40-I39))),J40+((F20-I40)*(J41-J40)/(I41-I40))),J41) -> 40.8 | L20: =IF(F20>I51,IF(F20>I50,IF(F20>I49,IF(F20>I48,IF(F20>I47,J47,J47+((F20-I47)*(J48-J47)/(I48-I47))),J48+((F20-I48)*(J49-J48)/(I49-I48))),J49+((F20-I49)*(J50-J49)/(I50-I49))),J50+((F20-I50)*(J51-J50)/(I51-I50))),J51) -> 27.6 | N20: =IF('Sección 1.1'!$D$10>='Sección 1.1'!M37,'Sección 1.1'!N37,IF(AND('Sección 1.1'!$D$10>='Sección 1.1'!M38,'Sección 1.1'!$D$10<'Sección 1.1'!M37),'Sección 1.1'!N38,IF(AND('Sección 1.1'!$D$10>='Sección 1.1'!M39,'Sección 1.1'!$D$10<'Sección 1.1'!M38),'Sección 1.1'!N39,IF(AND('Sección 1.1'!$D$10>='Sección 1.1'!M40,'Sección 1.1'!$D$10<'Sección 1.1'!M39),'Sección 1.1'!N40,IF(AND('Sección 1.1'!$D$10>='Sección 1.1'!M41,'Sección 1.1'!$D$10<'Sección 1.1'!M40),'Sección 1.1'!N41,IF(AND('Sección 1.1'!$D$10>='Sección 1.1'!M42,'Sección 1.1'!$D$10<'Sección 1.1'!M41),'Sección 1.1'!N42,N43)))))) -> A
C21: Potencia Instalada | D21: P | E21: W | F21: =SUM(F22:F23) -> 84 | G21: (autocalculado)
C22: Potencia lámpara | D22: Pl | E22: W | F22: =33+51 -> 84 | H22: POTENCIA UNIT MÁXIMA
C23: Potencia equipo | D23: Pe | E23: W | F23: 0 | H23: Vial | I23: Camino
C24: Factor de mantenimiento | D24: Fm | E24: - | F24: 0.8 | H24: =IF(F20>F41,IF(F20>F40,IF(F20>F39,IF(F20>F38,IF(F20>F37,IF(F20>F36,G36,G36+((F20-F36)*(G37-G36)/(F37-F36))),G37+((F20-F37)*(G38-G37)/(F38-F37))),G38+((F20-F38)*(G39-G38)/(F39-F38))),G39+((F20-F39)*(G40-G39)/(F40-F39))),G40+((F20-F40)*(G41-G40)/(F41-F40))),G41) -> 0.398 | I24: =IF(F20>F51,IF(F20>F50,IF(F20>F49,IF(F20>F48,IF(F20>F47,G47,G47+((F20-F47)*(G48-G47)/(F48-F47))),G48+((F20-F48)*(G49-G48)/(F49-F48))),G49+((F20-F49)*(G50-G49)/(F50-F49))),G50+((F20-F50)*(G51-G50)/(F51-F50))),G51) -> 0.78
C25: Eficiencia lámpara | D25: el | E25: lum/W | F25: =F26/F21 -> 154.7619 | G25: (autocalculado)
C26: Flujo lámpara | D26: Fl | E26: lum | F26: =8000+5000 -> 13000
C27: Situación Proyecto | F27: B1
C28: Clase de Alumbrado | F28: ME2
C29: Vial/Camino | E29: V/C | F29: V
C30: Potencia unitaria (W/m²) | F30: =F21/F19 -> 0.26794258
C33: Tabla 1 - Eficiencia Viales | F33: Tabla 1 - Potencia unitaria | I33: Tabla 3 - Eficiencia referencia Viales | M33: Tabla 4 - Calificación Energética
C35: Em(lux) | D35: emínima | F35: Em(lux) | G35: emínima | I35: Em(lux) | J35: emínima | M35: I. Eficiencia | N35: Calificación
C36: 30 | D36: 36 | F36: 30 | G36: 0.83 | I36: 30 | J36: 68
C37: 25 | D37: 35 | F37: 25 | G37: 0.71 | I37: 25 | J37: 60 | M37: 1.1 | N37: A
C38: 20 | D38: 34 | F38: 20 | G38: 0.59 | I38: 20 | J38: 52 | M38: 0.92 | N38: B
C39: 15 | D39: 33 | F39: 15 | G39: 0.45 | I39: 15 | J39: 44 | M39: 0.74 | N39: C
C40: 10 | D40: 31 | F40: 10 | G40: 0.32 | I40: 10 | J40: 36 | M40: 0.56 | N40: D
C41: 7.5 | D41: 29 | F41: 7.5 | G41: 0.26 | I41: 7.5 | J41: 28 | M41: 0.38 | N41: E
M42: 0.2 | N42: F
N43: G
C44: Tabla 2 - Eficiencia Caminos | F44: Tabla 1 - Potencia unitaria | I44: Tabla 3 - Eficiencia referencia caminos
C46: Em(lux) | D46: emínima | F46: Em(lux) | G46: emínima | I46: Em(lux) | J46: emínima
C47: 20 | D47: 18 | F47: 20 | G47: 1.11 | I47: 20 | J47: 36
C48: 15 | D48: 17 | F48: 15 | G48: 0.88 | I48: 15 | J48: 30
...

Sheet Sección 1.3
C2: SECCIÓN 1.3
C4: SITUACIÓN DE PROYECTO | D4: ='Sección 1.3'!$F$27 -> B1
C5: CLASE DE ALUMBRADO | D5: ='Sección 1.3'!$F$28 -> ME2
C6: VALOR DE EFICIENCIA ENERGÉTICA = | D6: =('Sección 1.3'!F19*'Sección 1.3'!F20)/'Sección 1.3'!F21 -> 67.356863
C7: VALOR DE EFICIENCIA ENERGÉTICA MÍNIMA = | D7: =IF('Sección 1.3'!F29="v",'Sección 1.3'!H20,'Sección 1.3'!I20) -> 33.2
C8: EFICIENCIA>EFICIENCIA MÍNIMA | D8: =IF(D7<=D6,"CUMPLE","NO CUMPLE") -> CUMPLE
C9: EFICIENCIA ENERGÉTICA DE REFERENCIA | D9: =IF('Sección 1.3'!F29="v",'Sección 1.3'!K20,'Sección 1.3'!L20) -> 45.6
C10: INDICE DE EFICIENCIA ENERGÉTICA = | D10: =D6/D9 -> 1.4771242
C11: CLASIFICACIÓN ENERGÉTICA DE LA INSTALACIÓN = | D11: ='Sección 1.3'!N20 -> A
C12: FACTOR DE UTILIZACIÓN = | D12: =D6/(F25*F24) -> 0.53675
C13: POTENCIA UNITARIA<POTENCIA UNITARIA MÁXIMA | D13: =IF(F30<=H24,"CUMPLE","NO CUMPLE") -> CUMPLE
C15: CALCULOS
C17: Dato | D17: Referencia | E17: Ud | F17: Valor
H18: EFICIENCIA MÍNIMA | K18: EFICIENCIA REFERENCIA | N18: CALIFICACIÓN ENERGÉTICA
C19: Superficie | D19: S | E19: m2 | F19: =19*22.6 -> 429.4 | H19: Vial | I19: Camino | K19: Vial | L19: Camino
C20: Iluminancia Media | D20: Em | E20: lux | F20: 16 | H20: =IF(F20>C41,IF(F20>C40,IF(F20>C39,IF(F20>C38,IF(F20>C37,IF(F20>C36,D36,D36+((F20-C36)*(D37-D36)/(C37-C36))),D37+((F20-C37)*(D38-D37)/(C38-C37))),D38+((F20-C38)*(D39-D38)/(C39-C38))),D39+((F20-C39)*(D40-D39)/(C40-C39))),D40+((F20-C40)*(D41-D40)/(C41-C40))),D41) -> 33.2 | I20: =IF(F20>C51,IF(F20>C50,IF(F20>C49,IF(F20>C48,IF(F20>C47,D47,D47+((F20-C47)*(D48-D47)/(C48-C47))),D48+((F20-C48)*(D49-D48)/(C49-C48))),D49+((F20-C49)*(D50-D49)/(C50-C49))),D50+((F20-C50)*(D51-D50)/(C51-C50))),D51) -> 17.2 | K20: =IF(F20>I41,IF(F20>I40,IF(F20>I39,IF(F20>I38,IF(F20>I37,IF(F20>I36,J36,J36+((F20-I36)*(J37-J36)/(I37-I36))),J37+((F20-I37)*(J38-J37)/(I38-I37))),J38+((F20-I38)*(J39-J38)/(I39-I38))),J39+((F20-I39)*(J40-J39)/(I40-I39))),J40+((F20-I40)*(J41-J40)/(I41-I40))),J41) -> 45.6 | L20: =IF(F20>I51,IF(F20>I50,IF(F20>I49,IF(F20>I48,IF(F20>I47,J47,J47+((F20-I47)*(J48-J47)/(I48-I47))),J48+((F20-I48)*(J49-J48)/(I49-I48))),J49+((F20-I49)*(J50-J49)/(I50-I49))),J50+((F20-I50)*(J51-J50)/(I51-I50))),J51) -> 31.2 | N20: =IF('Sección 1.3'!$D$10>='Sección 1.3'!M37,'Sección 1.3'!N37,IF(AND('Sección 1.3'!$D$10>='Sección 1.3'!M38,'Sección 1.3'!$D$10<'Sección 1.3'!M37),'Sección 1.3'!N38,IF(AND('Sección 1.3'!$D$10>='Sección 1.3'!M39,'Sección 1.3'!$D$10<'Sección 1.3'!M38),'Sección 1.3'!N39,IF(AND('Sección 1.3'!$D$10>='Sección 1.3'!M40,'Sección 1.3'!$D$10<'Sección 1.3'!M39),'Sección 1.3'!N40,IF(AND('Sección 1.3'!$D$10>='Sección 1.3'!M41,'Sección 1.3'!$D$10<'Sección 1.3'!M40),'Sección 1.3'!N41,IF(AND('Sección 1.3'!$D$10>='Sección 1.3'!M42,'Sección 1.3'!$D$10<'Sección 1.3'!M41),'Sección 1.3'!N42,N43)))))) -> A
C21: Potencia Instalada | D21: P | E21: W | F21: =SUM(F22:F23) -> 102 | G21: (autocalculado)
C22: Potencia lámpara | D22: Pl | E22: W | F22: =2*51 -> 102 | H22: POTENCIA UNIT MÁXIMA
C23: Potencia equipo | D23: Pe | E23: W | F23: 0 | H23: Vial | I23: Camino
C24: Factor de mantenimiento | D24: Fm | E24: - | F24: 0.8 | H24: =IF(F20>F41,IF(F20>F40,IF(F20>F39,IF(F20>F38,IF(F20>F37,IF(F20>F36,G36,G36+((F20-F36)*(G37-G36)/(F37-F36))),G37+((F20-F37)*(G38-G37)/(F38-F37))),G38+((F20-F38)*(G39-G38)/(F39-F38))),G39+((F20-F39)*(G40-G39)/(F40-F39))),G40+((F20-F40)*(G41-G40)/(F41-F40))),G41) -> 0.478 | I24: =IF(F20>F51,IF(F20>F50,IF(F20>F49,IF(F20>F48,IF(F20>F47,G47,G47+((F20-F47)*(G48-G47)/(F48-F47))),G48+((F20-F48)*(G49-G48)/(F49-F48))),G49+((F20-F49)*(G50-G49)/(F50-F49))),G50+((F20-F50)*(G51-G50)/(F51-F50))),G51) -> 0.926
C25: Eficiencia lámpara | D25: el | E25: lum/W | F25: =F26/F21 -> 156.86275 | G25: (autocalculado)
C26: Flujo lámpara | D26: Fl | E26: lum | F26: =8000*2 -> 16000
C27: Situación Proyecto | F27: B1
C28: Clase de Alumbrado | F28: ME2
C29: Vial/Camino | E29: V/C | F29: V
C30: Potencia unitaria (W/m²) | F30: =F21/F19 -> 0.23754075
C33: Tabla 1 - Eficiencia Viales | F33: Tabla 1 - Potencia unitaria | I33: Tabla 3 - Eficiencia referencia Viales | M33: Tabla 4 - Calificación Energética
C35: Em(lux) | D35: emínima | F35: Em(lux) | G35: emínima | I35: Em(lux) | J35: emínima | M35: I. Eficiencia | N35: Calificación
C36: 30 | D36: 36 | F36: 30 | G36: 0.83 | I36: 30 | J36: 68
C37: 25 | D37: 35 | F37: 25 | G37: 0.71 | I37: 25 | J37: 60 | M37: 1.1 | N37: A
C38: 20 | D38: 34 | F38: 20 | G38: 0.59 | I38: 20 | J38: 52 | M38: 0.92 | N38: B
C39: 15 | D39: 33 | F39: 15 | G39: 0.45 | I39: 15 | J39: 44 | M39: 0.74 | N39: C
C40: 10 | D40: 31 | F40: 10 | G40: 0.32 | I40: 10 | J40: 36 | M40: 0.56 | N40: D
C41: 7.5 | D41: 29 | F41: 7.5 | G41: 0.26 | I41: 7.5 | J41: 28 | M41: 0.38 | N41: E
M42: 0.2 | N42: F
N43: G
C44: Tabla 2 - Eficiencia Caminos | F44: Tabla 1 - Potencia unitaria | I44: Tabla 3 - Eficiencia referencia caminos
C46: Em(lux) | D46: emínima | F46: Em(lux) | G46: emínima | I46: Em(lux) | J46: emínima
C47: 20 | D47: 18 | F47: 20 | G47: 1.11 | I47: 20 | J47: 36
C48: 15 | D48: 17 | F48: 15 | G48: 0.88 | I48: 15 | J48: 30
...

Sheet Sección 1.4
C2: SECCIÓN 1.4
C4: SITUACIÓN DE PROYECTO | D4: ='Sección 1.4'!$F$27 -> B1
C5: CLASE DE ALUMBRADO | D5: ='Sección 1.4'!$F$28 -> ME2
C6: VALOR DE EFICIENCIA ENERGÉTICA = | D6: =('Sección 1.4'!F19*'Sección 1.4'!F20)/'Sección 1.4'!F21 -> 65.941176
C7: VALOR DE EFICIENCIA ENERGÉTICA MÍNIMA = | D7: =IF('Sección 1.4'!F29="v",'Sección 1.4'!H20,'Sección 1.4'!I20) -> 33
C8: EFICIENCIA>EFICIENCIA MÍNIMA | D8: =IF(D7<=D6,"CUMPLE","NO CUMPLE") -> CUMPLE
C9: EFICIENCIA ENERGÉTICA DE REFERENCIA | D9: =IF('Sección 1.4'!F29="v",'Sección 1.4'!K20,'Sección 1.4'!L20) -> 44
C10: INDICE DE EFICIENCIA ENERGÉTICA = | D10: =D6/D9 -> 1.4986631
C11: CLASIFICACIÓN ENERGÉTICA DE LA INSTALACIÓN = | D11: ='Sección 1.4'!N20 -> A
C12: FACTOR DE UTILIZACIÓN = | D12: =D6/(F25*F24) -> 0.52546875
C13: POTENCIA UNITARIA<POTENCIA UNITARIA MÁXIMA | D13: =IF(F30<=H24,"CUMPLE","NO CUMPLE") -> CUMPLE
C15: CALCULOS
C17: Dato | D17: Referencia | E17: Ud | F17: Valor
H18: EFICIENCIA MÍNIMA | K18: EFICIENCIA REFERENCIA | N18: CALIFICACIÓN ENERGÉTICA
C19: Superficie | D19: S | E19: m2 | F19: =19*23.6 -> 448.4 | H19: Vial | I19: Camino | K19: Vial | L19: Camino
C20: Iluminancia Media | D20: Em | E20: lux | F20: 15 | H20: =IF(F20>C41,IF(F20>C40,IF(F20>C39,IF(F20>C38,IF(F20>C37,IF(F20>C36,D36,D36+((F20-C36)*(D37-D36)/(C37-C36))),D37+((F20-C37)*(D38-D37)/(C38-C37))),D38+((F20-C38)*(D39-D38)/(C39-C38))),D39+((F20-C39)*(D40-D39)/(C40-C39))),D40+((F20-C40)*(D41-D40)/(C41-C40))),D41) -> 33 | I20: =IF(F20>C51,IF(F20>C50,IF(F20>C49,IF(F20>C48,IF(F20>C47,D47,D47+((F20-C47)*(D48-D47)/(C48-C47))),D48+((F20-C48)*(D49-D48)/(C49-C48))),D49+((F20-C49)*(D50-D49)/(C50-C49))),D50+((F20-C50)*(D51-D50)/(C51-C50))),D51) -> 17 | K20: =IF(F20>I41,IF(F20>I40,IF(F20>I39,IF(F20>I38,IF(F20>I37,IF(F20>I36,J36,J36+((F20-I36)*(J37-J36)/(I37-I36))),J37+((F20-I37)*(J38-J37)/(I38-I37))),J38+((F20-I38)*(J39-J38)/(I39-I38))),J39+((F20-I39)*(J40-J39)/(I40-I39))),J40+((F20-I40)*(J41-J40)/(I41-I40))),J41) -> 44 | L20: =IF(F20>I51,IF(F20>I50,IF(F20>I49,IF(F20>I48,IF(F20>I47,J47,J47+((F20-I47)*(J48-J47)/(I48-I47))),J48+((F20-I48)*(J49-J48)/(I49-I48))),J49+((F20-I49)*(J50-J49)/(I50-I49))),J50+((F20-I50)*(J51-J50)/(I51-I50))),J51) -> 30 | N20: =IF('Sección 1.4'!$D$10>='Sección 1.4'!M37,'Sección 1.4'!N37,IF(AND('Sección 1.4'!$D$10>='Sección 1.4'!M38,'Sección 1.4'!$D$10<'Sección 1.4'!M37),'Sección 1.4'!N38,IF(AND('Sección 1.4'!$D$10>='Sección 1.4'!M39,'Sección 1.4'!$D$10<'Sección 1.4'!M38),'Sección 1.4'!N39,IF(AND('Sección 1.4'!$D$10>='Sección 1.4'!M40,'Sección 1.4'!$D$10<'Sección 1.4'!M39),'Sección 1.4'!N40,IF(AND('Sección 1.4'!$D$10>='Sección 1.4'!M41,'Sección 1.4'!$D$10<'Sección 1.4'!M40),'Sección 1.4'!N41,IF(AND('Sección 1.4'!$D$10>='Sección 1.4'!M42,'Sección 1.4'!$D$10<'Sección 1.4'!M41),'Sección 1.4'!N42,N43)))))) -> A
C21: Potencia Instalada | D21: P | E21: W | F21: =SUM(F22:F23) -> 102 | G21: (autocalculado)
C22: Potencia lámpara | D22: Pl | E22: W | F22: =2*51 -> 102 | H22: POTENCIA UNIT MÁXIMA
C23: Potencia equipo | D23: Pe | E23: W | F23: 0 | H23: Vial | I23: Camino
C24: Factor de mantenimiento | D24: Fm | E24: - | F24: 0.8 | H24: =IF(F20>F41,IF(F20>F40,IF(F20>F39,IF(F20>F38,IF(F20>F37,IF(F20>F36,G36,G36+((F20-F36)*(G37-G36)/(F37-F36))),G37+((F20-F37)*(G38-G37)/(F38-F37))),G38+((F20-F38)*(G39-G38)/(F39-F38))),G39+((F20-F39)*(G40-G39)/(F40-F39))),G40+((F20-F40)*(G41-G40)/(F41-F40))),G41) -> 0.45 | I24: =IF(F20>F51,IF(F20>F50,IF(F20>F49,IF(F20>F48,IF(F20>F47,G47,G47+((F20-F47)*(G48-G47)/(F48-F47))),G48+((F20-F48)*(G49-G48)/(F49-F48))),G49+((F20-F49)*(G50-G49)/(F50-F49))),G50+((F20-F50)*(G51-G50)/(F51-F50))),G51) -> 0.88
C25: Eficiencia lámpara | D25: el | E25: lum/W | F25: =F26/F21 -> 156.86275 | G25: (autocalculado)
C26: Flujo lámpara | D26: Fl | E26: lum | F26: =8000*2 -> 16000
C27: Situación Proyecto | F27: B1
C28: Clase de Alumbrado | F28: ME2
C29: Vial/Camino | E29: V/C | F29: V
C30: Potencia unitaria (W/m²) | F30: =F21/F19 -> 0.22747547
C33: Tabla 1 - Eficiencia Viales | F33: Tabla 1 - Potencia unitaria | I33: Tabla 3 - Eficiencia referencia Viales | M33: Tabla 4 - Calificación Energética
C35: Em(lux) | D35: emínima | F35: Em(lux) | G35: emínima | I35: Em(lux) | J35: emínima | M35: I. Eficiencia | N35: Calificación
C36: 30 | D36: 36 | F36: 30 | G36: 0.83 | I36: 30 | J36: 68
C37: 25 | D37: 35 | F37: 25 | G37: 0.71 | I37: 25 | J37: 60 | M37: 1.1 | N37: A
C38: 20 | D38: 34 | F38: 20 | G38: 0.59 | I38: 20 | J38: 52 | M38: 0.92 | N38: B
C39: 15 | D39: 33 | F39: 15 | G39: 0.45 | I39: 15 | J39: 44 | M39: 0.74 | N39: C
C40: 10 | D40: 31 | F40: 10 | G40: 0.32 | I40: 10 | J40: 36 | M40: 0.56 | N40: D
C41: 7.5 | D41: 29 | F41: 7.5 | G41: 0.26 | I41: 7.5 | J41: 28 | M41: 0.38 | N41: E
M42: 0.2 | N42: F
N43: G
C44: Tabla 2 - Eficiencia Caminos | F44: Tabla 1 - Potencia unitaria | I44: Tabla 3 - Eficiencia referencia caminos
C46: Em(lux) | D46: emínima | F46: Em(lux) | G46: emínima | I46: Em(lux) | J46: emínima
C47: 20 | D47: 18 | F47: 20 | G47: 1.11 | I47: 20 | J47: 36
C48: 15 | D48: 17 | F48: 15 | G48: 0.88 | I48: 15 | J48: 30
...

Sheet Sección 1.6
C2: SECCIÓN 1.6
C4: SITUACIÓN DE PROYECTO | D4: ='Sección 1.6'!$F$27 -> B1
C5: CLASE DE ALUMBRADO | D5: ='Sección 1.6'!$F$28 -> ME2
C6: VALOR DE EFICIENCIA ENERGÉTICA = | D6: =('Sección 1.6'!F19*'Sección 1.6'!F20)/'Sección 1.6'!F21 -> 46.428876
C7: VALOR DE EFICIENCIA ENERGÉTICA MÍNIMA = | D7: =IF('Sección 1.6'!F29="v",'Sección 1.6'!H20,'Sección 1.6'!I20) -> 30.496
C8: EFICIENCIA>EFICIENCIA MÍNIMA | D8: =IF(D7<=D6,"CUMPLE","NO CUMPLE") -> CUMPLE
C9: EFICIENCIA ENERGÉTICA DE REFERENCIA | D9: =IF('Sección 1.6'!F29="v",'Sección 1.6'!K20,'Sección 1.6'!L20) -> 33.984
C10: INDICE DE EFICIENCIA ENERGÉTICA = | D10: =D6/D9 -> 1.3661981
C11: CLASIFICACIÓN ENERGÉTICA DE LA INSTALACIÓN = | D11: ='Sección 1.6'!N20 -> A
C12: FACTOR DE UTILIZACIÓN = | D12: =D6/(F25*F24) -> 0.36894375
C13: POTENCIA UNITARIA<POTENCIA UNITARIA MÁXIMA | D13: =IF(F30<=H24,"CUMPLE","NO CUMPLE") -> CUMPLE
C15: CALCULOS
C17: Dato | D17: Referencia | E17: Ud | F17: Valor
H18: EFICIENCIA MÍNIMA | K18: EFICIENCIA REFERENCIA | N18: CALIFICACIÓN ENERGÉTICA
C19: Superficie | D19: S | E19: m2 | F19: =30*14.7 -> 441 | H19: Vial | I19: Camino | K19: Vial | L19: Camino
C20: Iluminancia Media | D20: Em | E20: lux | F20: 9.37 | H20: =IF(F20>C41,IF(F20>C40,IF(F20>C39,IF(F20>C38,IF(F20>C37,IF(F20>C36,D36,D36+((F20-C36)*(D37-D36)/(C37-C36))),D37+((F20-C37)*(D38-D37)/(C38-C37))),D38+((F20-C38)*(D39-D38)/(C39-C38))),D39+((F20-C39)*(D40-D39)/(C40-C39))),D40+((F20-C40)*(D41-D40)/(C41-C40))),D41) -> 30.496 | I20: =IF(F20>C51,IF(F20>C50,IF(F20>C49,IF(F20>C48,IF(F20>C47,D47,D47+((F20-C47)*(D48-D47)/(C48-C47))),D48+((F20-C48)*(D49-D48)/(C49-C48))),D49+((F20-C49)*(D50-D49)/(C50-C49))),D50+((F20-C50)*(D51-D50)/(C51-C50))),D51) -> 15.496 | K20: =IF(F20>I41,IF(F20>I40,IF(F20>I39,IF(F20>I38,IF(F20>I37,IF(F20>I36,J36,J36+((F20-I36)*(J37-J36)/(I37-I36))),J37+((F20-I37)*(J38-J37)/(I38-I37))),J38+((F20-I38)*(J39-J38)/(I39-I38))),J39+((F20-I39)*(J40-J39)/(I40-I39))),J40+((F20-I40)*(J41-J40)/(I41-I40))),J41) -> 33.984 | L20: =IF(F20>I51,IF(F20>I50,IF(F20>I49,IF(F20>I48,IF(F20>I47,J47,J47+((F20-I47)*(J48-J47)/(I48-I47))),J48+((F20-I48)*(J49-J48)/(I49-I48))),J49+((F20-I49)*(J50-J49)/(I50-I49))),J50+((F20-I50)*(J51-J50)/(I51-I50))),J51) -> 22.488 | N20: =IF('Sección 1.6'!$D$10>='Sección 1.6'!M37,'Sección 1.6'!N37,IF(AND('Sección 1.6'!$D$10>='Sección 1.6'!M38,'Sección 1.6'!$D$10<'Sección 1.6'!M37),'Sección 1.6'!N38,IF(AND('Sección 1.6'!$D$10>='Sección 1.6'!M39,'Sección 1.6'!$D$10<'Sección 1.6'!M38),'Sección 1.6'!N39,IF(AND('Sección 1.6'!$D$10>='Sección 1.6'!M40,'Sección 1.6'!$D$10<'Sección 1.6'!M39),'Sección 1.6'!N40,IF(AND('Sección 1.6'!$D$10>='Sección 1.6'!M41,'Sección 1.6'!$D$10<'Sección 1.6'!M40),'Sección 1.6'!N41,IF(AND('Sección 1.6'!$D$10>='Sección 1.6'!M42,'Sección 1.6'!$D$10<'Sección 1.6'!M41),'Sección 1.6'!N42,N43)))))) -> A
C21: Potencia Instalada | D21: P | E21: W | F21: =SUM(F22:F23) -> 89 | G21: (autocalculado)
C22: Potencia lámpara | D22: Pl | E22: W | F22: =2*44.5 -> 89 | H22: POTENCIA UNIT MÁXIMA
C23: Potencia equipo | D23: Pe | E23: W | F23: 0 | H23: Vial | I23: Camino
C24: Factor de mantenimiento | D24: Fm | E24: - | F24: 0.8 | H24: =IF(F20>F41,IF(F20>F40,IF(F20>F39,IF(F20>F38,IF(F20>F37,IF(F20>F36,G36,G36+((F20-F36)*(G37-G36)/(F37-F36))),G37+((F20-F37)*(G38-G37)/(F38-F37))),G38+((F20-F38)*(G39-G38)/(F39-F38))),G39+((F20-F39)*(G40-G39)/(F40-F39))),G40+((F20-F40)*(G41-G40)/(F41-F40))),G41) -> 0.30488 | I24: =IF(F20>F51,IF(F20>F50,IF(F20>F49,IF(F20>F48,IF(F20>F47,G47,G47+((F20-F47)*(G48-G47)/(F48-F47))),G48+((F20-F48)*(G49-G48)/(F49-F48))),G49+((F20-F49)*(G50-G49)/(F50-F49))),G50+((F20-F50)*(G51-G50)/(F51-F50))),G51) -> 0.6048
C25: Eficiencia lámpara | D25: el | E25: lum/W | F25: =F26/F21 -> 157.30337 | G25: (autocalculado)
C26: Flujo lámpara | D26: Fl | E26: lum | F26: =7000*2 -> 14000
C27: Situación Proyecto | F27: B1
C28: Clase de Alumbrado | F28: ME2
C29: Vial/Camino | E29: V/C | F29: V
C30: Potencia unitaria (W/m²) | F30: =F21/F19 -> 0.20181406
C33: Tabla 1 - Eficiencia Viales | F33: Tabla 1 - Potencia unitaria | I33: Tabla 3 - Eficiencia referencia Viales | M33: Tabla 4 - Calificación Energética
C35: Em(lux) | D35: emínima | F35: Em(lux) | G35: emínima | I35: Em(lux) | J35: emínima | M35: I. Eficiencia | N35: Calificación
C36: 30 | D36: 36 | F36: 30 | G36: 0.83 | I36: 30 | J36: 68
C37: 25 | D37: 35 | F37: 25 | G37: 0.71 | I37: 25 | J37: 60 | M37: 1.1 | N37: A
C38: 20 | D38: 34 | F38: 20 | G38: 0.59 | I38: 20 | J38: 52 | M38: 0.92 | N38: B
C39: 15 | D39: 33 | F39: 15 | G39: 0.45 | I39: 15 | J39: 44 | M39: 0.74 | N39: C
C40: 10 | D40: 31 | F40: 10 | G40: 0.32 | I40: 10 | J40: 36 | M40: 0.56 | N40: D
C41: 7.5 | D41: 29 | F41: 7.5 | G41: 0.26 | I41: 7.5 | J41: 28 | M41: 0.38 | N41: E
M42: 0.2 | N42: F
N43: G
C44: Tabla 2 - Eficiencia Caminos | F44: Tabla 1 - Potencia unitaria | I44: Tabla 3 - Eficiencia referencia caminos
C46: Em(lux) | D46: emínima | F46: Em(lux) | G46: emínima | I46: Em(lux) | J46: emínima
C47: 20 | D47: 18 | F47: 20 | G47: 1.11 | I47: 20 | J47: 36
C48: 15 | D48: 17 | F48: 15 | G48: 0.88 | I48: 15 | J48: 30
...

Sheet Sección 2.1
C2: SECCIÓN 2.1
C4: SITUACIÓN DE PROYECTO | D4: ='Sección 2.1'!$F$27 -> B1
C5: CLASE DE ALUMBRADO | D5: ='Sección 2.1'!$F$28 -> ME2
C6: VALOR DE EFICIENCIA ENERGÉTICA = | D6: =('Sección 2.1'!F19*'Sección 2.1'!F20)/'Sección 2.1'!F21 -> 52.724138
C7: VALOR DE EFICIENCIA ENERGÉTICA MÍNIMA = | D7: =IF('Sección 2.1'!F29="v",'Sección 2.1'!H20,'Sección 2.1'!I20) -> 31.4
C8: EFICIENCIA>EFICIENCIA MÍNIMA | D8: =IF(D7<=D6,"CUMPLE","NO CUMPLE") -> CUMPLE
C9: EFICIENCIA ENERGÉTICA DE REFERENCIA | D9: =IF('Sección 2.1'!F29="v",'Sección 2.1'!K20,'Sección 2.1'!L20) -> 37.6
C10: INDICE DE EFICIENCIA ENERGÉTICA = | D10: =D6/D9 -> 1.4022377
C11: CLASIFICACIÓN ENERGÉTICA DE LA INSTALACIÓN = | D11: ='Sección 2.1'!N20 -> A
C12: FACTOR DE UTILIZACIÓN = | D12: =D6/(F25*F24) -> 0.40955357
C13: POTENCIA UNITARIA<POTENCIA UNITARIA MÁXIMA | D13: =IF(F30<=H24,"CUMPLE","NO CUMPLE") -> CUMPLE
C15: CALCULOS
C17: Dato | D17: Referencia | E17: Ud | F17: Valor
H18: EFICIENCIA MÍNIMA | K18: EFICIENCIA REFERENCIA | N18: CALIFICACIÓN ENERGÉTICA
C19: Superficie | D19: S | E19: m2 | F19: =13.9*30 -> 417 | H19: Vial | I19: Camino | K19: Vial | L19: Camino
C20: Iluminancia Media | D20: Em | E20: lux | F20: 11 | H20: =IF(F20>C41,IF(F20>C40,IF(F20>C39,IF(F20>C38,IF(F20>C37,IF(F20>C36,D36,D36+((F20-C36)*(D37-D36)/(C37-C36))),D37+((F20-C37)*(D38-D37)/(C38-C37))),D38+((F20-C38)*(D39-D38)/(C39-C38))),D39+((F20-C39)*(D40-D39)/(C40-C39))),D40+((F20-C40)*(D41-D40)/(C41-C40))),D41) -> 31.4 | I20: =IF(F20>C51,IF(F20>C50,IF(F20>C49,IF(F20>C48,IF(F20>C47,D47,D47+((F20-C47)*(D48-D47)/(C48-C47))),D48+((F20-C48)*(D49-D48)/(C49-C48))),D49+((F20-C49)*(D50-D49)/(C50-C49))),D50+((F20-C50)*(D51-D50)/(C51-C50))),D51) -> 16.2 | K20: =IF(F20>I41,IF(F20>I40,IF(F20>I39,IF(F20>I38,IF(F20>I37,IF(F20>I36,J36,J36+((F20-I36)*(J37-J36)/(I37-I36))),J37+((F20-I37)*(J38-J37)/(I38-I37))),J38+((F20-I38)*(J39-J38)/(I39-I38))),J39+((F20-I39)*(J40-J39)/(I40-I39))),J40+((F20-I40)*(J41-J40)/(I41-I40))),J41) -> 37.6 | L20: =IF(F20>I51,IF(F20>I50,IF(F20>I49,IF(F20>I48,IF(F20>I47,J47,J47+((F20-I47)*(J48-J47)/(I48-I47))),J48+((F20-I48)*(J49-J48)/(I49-I48))),J49+((F20-I49)*(J50-J49)/(I50-I49))),J50+((F20-I50)*(J51-J50)/(I51-I50))),J51) -> 25.2 | N20: =IF('Sección 2.1'!$D$10>='Sección 2.1'!M37,'Sección 2.1'!N37,IF(AND('Sección 2.1'!$D$10>='Sección 2.1'!M38,'Sección 2.1'!$D$10<'Sección 2.1'!M37),'Sección 2.1'!N38,IF(AND('Sección 2.1'!$D$10>='Sección 2.1'!M39,'Sección 2.1'!$D$10<'Sección 2.1'!M38),'Sección 2.1'!N39,IF(AND('Sección 2.1'!$D$10>='Sección 2.1'!M40,'Sección 2.1'!$D$10<'Sección 2.1'!M39),'Sección 2.1'!N40,IF(AND('Sección 2.1'!$D$10>='Sección 2.1'!M41,'Sección 2.1'!$D$10<'Sección 2.1'!M40),'Sección 2.1'!N41,IF(AND('Sección 2.1'!$D$10>='Sección 2.1'!M42,'Sección 2.1'!$D$10<'Sección 2.1'!M41),'Sección 2.1'!N42,N43)))))) -> A
C21: Potencia Instalada | D21: P | E21: W | F21: =SUM(F22:F23) -> 87 | G21: (autocalculado)
C22: Potencia lámpara | D22: Pl | E22: W | F22: 87 | H22: POTENCIA UNIT MÁXIMA
C23: Potencia equipo | D23: Pe | E23: W | F23: 0 | H23: Vial | I23: Camino
C24: Factor de mantenimiento | D24: Fm | E24: - | F24: 0.8 | H24: =IF(F20>F41,IF(F20>F40,IF(F20>F39,IF(F20>F38,IF(F20>F37,IF(F20>F36,G36,G36+((F20-F36)*(G37-G36)/(F37-F36))),G37+((F20-F37)*(G38-G37)/(F38-F37))),G38+((F20-F38)*(G39-G38)/(F39-F38))),G39+((F20-F39)*(G40-G39)/(F40-F39))),G40+((F20-F40)*(G41-G40)/(F41-F40))),G41) -> 0.346 | I24: =IF(F20>F51,IF(F20>F50,IF(F20>F49,IF(F20>F48,IF(F20>F47,G47,G47+((F20-F47)*(G48-G47)/(F48-F47))),G48+((F20-F48)*(G49-G48)/(F49-F48))),G49+((F20-F49)*(G50-G49)/(F50-F49))),G50+((F20-F50)*(G51-G50)/(F51-F50))),G51) -> 0.68
C25: Eficiencia lámpara | D25: el | E25: lum/W | F25: =F26/F21 -> 160.91954 | G25: (autocalculado)
C26: Flujo lámpara | D26: Fl | E26: lum | F26: =14000 -> 14000
C27: Situación Proyecto | F27: B1
C28: Clase de Alumbrado | F28: ME2
C29: Vial/Camino | E29: V/C | F29: V
C30: Potencia unitaria (W/m²) | F30: =F21/F19 -> 0.20863309
C33: Tabla 1 - Eficiencia Viales | F33: Tabla 1 - Potencia unitaria | I33: Tabla 3 - Eficiencia referencia Viales | M33: Tabla 4 - Calificación Energética
C35: Em(lux) | D35: emínima | F35: Em(lux) | G35: emínima | I35: Em(lux) | J35: emínima | M35: I. Eficiencia | N35: Calificación
C36: 30 | D36: 36 | F36: 30 | G36: 0.83 | I36: 30 | J36: 68
C37: 25 | D37: 35 | F37: 25 | G37: 0.71 | I37: 25 | J37: 60 | M37: 1.1 | N37: A
C38: 20 | D38: 34 | F38: 20 | G38: 0.59 | I38: 20 | J38: 52 | M38: 0.92 | N38: B
C39: 15 | D39: 33 | F39: 15 | G39: 0.45 | I39: 15 | J39: 44 | M39: 0.74 | N39: C
C40: 10 | D40: 31 | F40: 10 | G40: 0.32 | I40: 10 | J40: 36 | M40: 0.56 | N40: D
C41: 7.5 | D41: 29 | F41: 7.5 | G41: 0.26 | I41: 7.5 | J41: 28 | M41: 0.38 | N41: E
M42: 0.2 | N42: F
N43: G
C44: Tabla 2 - Eficiencia Caminos | F44: Tabla 1 - Potencia unitaria | I44: Tabla 3 - Eficiencia referencia caminos
C46: Em(lux) | D46: emínima | F46: Em(lux) | G46: emínima | I46: Em(lux) | J46: emínima
C47: 20 | D47: 18 | F47: 20 | G47: 1.11 | I47: 20 | J47: 36
C48: 15 | D48: 17 | F48: 15 | G48: 0.88 | I48: 15 | J48: 30
...

Sheet Sección 2.2
C2: SECCIÓN 2.2
C4: SITUACIÓN DE PROYECTO | D4: ='Sección 2.2'!$F$27 -> B1
C5: CLASE DE ALUMBRADO | D5: ='Sección 2.2'!$F$28 -> ME2
C6: VALOR DE EFICIENCIA ENERGÉTICA = | D6: =('Sección 2.2'!F19*'Sección 2.2'!F20)/'Sección 2.2'!F21 -> 56.655738
C7: VALOR DE EFICIENCIA ENERGÉTICA MÍNIMA = | D7: =IF('Sección 2.2'!F29="v",'Sección 2.2'!H20,'Sección 2.2'!I20) -> 31.8
C8: EFICIENCIA>EFICIENCIA MÍNIMA | D8: =IF(D7<=D6,"CUMPLE","NO CUMPLE") -> CUMPLE
C9: EFICIENCIA ENERGÉTICA DE REFERENCIA | D9: =IF('Sección 2.2'!F29="v",'Sección 2.2'!K20,'Sección 2.2'!L20) -> 39.2
C10: INDICE DE EFICIENCIA ENERGÉTICA = | D10: =D6/D9 -> 1.4452994
C11: CLASIFICACIÓN ENERGÉTICA DE LA INSTALACIÓN = | D11: ='Sección 2.2'!N20 -> A
C12: FACTOR DE UTILIZACIÓN = | D12: =D6/(F25*F24) -> 0.432
C13: POTENCIA UNITARIA<POTENCIA UNITARIA MÁXIMA | D13: =IF(F30<=H24,"CUMPLE","NO CUMPLE") -> CUMPLE
C15: CALCULOS
C17: Dato | D17: Referencia | E17: Ud | F17: Valor
H18: EFICIENCIA MÍNIMA | K18: EFICIENCIA REFERENCIA | N18: CALIFICACIÓN ENERGÉTICA
C19: Superficie | D19: S | E19: m2 | F19: =19.2*30 -> 576 | H19: Vial | I19: Camino | K19: Vial | L19: Camino
C20: Iluminancia Media | D20: Em | E20: lux | F20: 12 | H20: =IF(F20>C41,IF(F20>C40,IF(F20>C39,IF(F20>C38,IF(F20>C37,IF(F20>C36,D36,D36+((F20-C36)*(D37-D36)/(C37-C36))),D37+((F20-C37)*(D38-D37)/(C38-C37))),D38+((F20-C38)*(D39-D38)/(C39-C38))),D39+((F20-C39)*(D40-D39)/(C40-C39))),D40+((F20-C40)*(D41-D40)/(C41-C40))),D41) -> 31.8 | I20: =IF(F20>C51,IF(F20>C50,IF(F20>C49,IF(F20>C48,IF(F20>C47,D47,D47+((F20-C47)*(D48-D47)/(C48-C47))),D48+((F20-C48)*(D49-D48)/(C49-C48))),D49+((F20-C49)*(D50-D49)/(C50-C49))),D50+((F20-C50)*(D51-D50)/(C51-C50))),D51) -> 16.4 | K20: =IF(F20>I41,IF(F20>I40,IF(F20>I39,IF(F20>I38,IF(F20>I37,IF(F20>I36,J36,J36+((F20-I36)*(J37-J36)/(I37-I36))),J37+((F20-I37)*(J38-J37)/(I38-I37))),J38+((F20-I38)*(J39-J38)/(I39-I38))),J39+((F20-I39)*(J40-J39)/(I40-I39))),J40+((F20-I40)*(J41-J40)/(I41-I40))),J41) -> 39.2 | L20: =IF(F20>I51,IF(F20>I50,IF(F20>I49,IF(F20>I48,IF(F20>I47,J47,J47+((F20-I47)*(J48-J47)/(I48-I47))),J48+((F20-I48)*(J49-J48)/(I49-I48))),J49+((F20-I49)*(J50-J49)/(I50-I49))),J50+((F20-I50)*(J51-J50)/(I51-I50))),J51) -> 26.4 | N20: =IF('Sección 2.2'!$D$10>='Sección 2.2'!M37,'Sección 2.2'!N37,IF(AND('Sección 2.2'!$D$10>='Sección 2.2'!M38,'Sección 2.2'!$D$10<'Sección 2.2'!M37),'Sección 2.2'!N38,IF(AND('Sección 2.2'!$D$10>='Sección 2.2'!M39,'Sección 2.2'!$D$10<'Sección 2.2'!M38),'Sección 2.2'!N39,IF(AND('Sección 2.2'!$D$10>='Sección 2.2'!M40,'Sección 2.2'!$D$10<'Sección 2.2'!M39),'Sección 2.2'!N40,IF(AND('Sección 2.2'!$D$10>='Sección 2.2'!M41,'Sección 2.2'!$D$10<'Sección 2.2'!M40),'Sección 2.2'!N41,IF(AND('Sección 2.2'!$D$10>='Sección 2.2'!M42,'Sección 2.2'!$D$10<'Sección 2.2'!M41),'Sección 2.2'!N42,N43)))))) -> A
C21: Potencia Instalada | D21: P | E21: W | F21: =SUM(F22:F23) -> 122 | G21: (autocalculado)
C22: Potencia lámpara | D22: Pl | E22: W | F22: =2*61 -> 122 | H22: POTENCIA UNIT MÁXIMA
C23: Potencia equipo | D23: Pe | E23: W | F23: 0 | H23: Vial | I23: Camino
C24: Factor de mantenimiento | D24: Fm | E24: - | F24: 0.8 | H24: =IF(F20>F41,IF(F20>F40,IF(F20>F39,IF(F20>F38,IF(F20>F37,IF(F20>F36,G36,G36+((F20-F36)*(G37-G36)/(F37-F36))),G37+((F20-F37)*(G38-G37)/(F38-F37))),G38+((F20-F38)*(G39-G38)/(F39-F38))),G39+((F20-F39)*(G40-G39)/(F40-F39))),G40+((F20-F40)*(G41-G40)/(F41-F40))),G41) -> 0.372 | I24: =IF(F20>F51,IF(F20>F50,IF(F20>F49,IF(F20>F48,IF(F20>F47,G47,G47+((F20-F47)*(G48-G47)/(F48-F47))),G48+((F20-F48)*(G49-G48)/(F49-F48))),G49+((F20-F49)*(G50-G49)/(F50-F49))),G50+((F20-F50)*(G51-G50)/(F51-F50))),G51) -> 0.73
C25: Eficiencia lámpara | D25: el | E25: lum/W | F25: =F26/F21 -> 163.93443 | G25: (autocalculado)
C26: Flujo lámpara | D26: Fl | E26: lum | F26: =10000*2 -> 20000
C27: Situación Proyecto | F27: B1
C28: Clase de Alumbrado | F28: ME2
C29: Vial/Camino | E29: V/C | F29: V
C30: Potencia unitaria (W/m²) | F30: =F21/F19 -> 0.21180556
C33: Tabla 1 - Eficiencia Viales | F33: Tabla 1 - Potencia unitaria | I33: Tabla 3 - Eficiencia referencia Viales | M33: Tabla 4 - Calificación Energética
C35: Em(lux) | D35: emínima | F35: Em(lux) | G35: emínima | I35: Em(lux) | J35: emínima | M35: I. Eficiencia | N35: Calificación
C36: 30 | D36: 36 | F36: 30 | G36: 0.83 | I36: 30 | J36: 68
C37: 25 | D37: 35 | F37: 25 | G37: 0.71 | I37: 25 | J37: 60 | M37: 1.1 | N37: A
C38: 20 | D38: 34 | F38: 20 | G38: 0.59 | I38: 20 | J38: 52 | M38: 0.92 | N38: B
C39: 15 | D39: 33 | F39: 15 | G39: 0.45 | I39: 15 | J39: 44 | M39: 0.74 | N39: C
C40: 10 | D40: 31 | F40: 10 | G40: 0.32 | I40: 10 | J40: 36 | M40: 0.56 | N40: D
C41: 7.5 | D41: 29 | F41: 7.5 | G41: 0.26 | I41: 7.5 | J41: 28 | M41: 0.38 | N41: E
M42: 0.2 | N42: F
N43: G
C44: Tabla 2 - Eficiencia Caminos | F44: Tabla 1 - Potencia unitaria | I44: Tabla 3 - Eficiencia referencia caminos
C46: Em(lux) | D46: emínima | F46: Em(lux) | G46: emínima | I46: Em(lux) | J46: emínima
C47: 20 | D47: 18 | F47: 20 | G47: 1.11 | I47: 20 | J47: 36
C48: 15 | D48: 17 | F48: 15 | G48: 0.88 | I48: 15 | J48: 30
...

Sheet Sección 2.3
C2: SECCIÓN 2.3
C4: SITUACIÓN DE PROYECTO | D4: ='Sección 2.3'!$F$27 -> B1
C5: CLASE DE ALUMBRADO | D5: ='Sección 2.3'!$F$28 -> ME2
C6: VALOR DE EFICIENCIA ENERGÉTICA = | D6: =('Sección 2.3'!F19*'Sección 2.3'!F20)/'Sección 2.3'!F21 -> 53.704918
C7: VALOR DE EFICIENCIA ENERGÉTICA MÍNIMA = | D7: =IF('Sección 2.3'!F29="v",'Sección 2.3'!H20,'Sección 2.3'!I20) -> 31.8
C8: EFICIENCIA>EFICIENCIA MÍNIMA | D8: =IF(D7<=D6,"CUMPLE","NO CUMPLE") -> CUMPLE
C9: EFICIENCIA ENERGÉTICA DE REFERENCIA | D9: =IF('Sección 2.3'!F29="v",'Sección 2.3'!K20,'Sección 2.3'!L20) -> 39.2
C10: INDICE DE EFICIENCIA ENERGÉTICA = | D10: =D6/D9 -> 1.3700234
C11: CLASIFICACIÓN ENERGÉTICA DE LA INSTALACIÓN = | D11: ='Sección 2.3'!N20 -> A
C12: FACTOR DE UTILIZACIÓN = | D12: =D6/(F25*F24) -> 0.4095
C13: POTENCIA UNITARIA<POTENCIA UNITARIA MÁXIMA | D13: =IF(F30<=H24,"CUMPLE","NO CUMPLE") -> CUMPLE
C15: CALCULOS
C17: Dato | D17: Referencia | E17: Ud | F17: Valor
H18: EFICIENCIA MÍNIMA | K18: EFICIENCIA REFERENCIA | N18: CALIFICACIÓN ENERGÉTICA
C19: Superficie | D19: S | E19: m2 | F19: =18.2*30 -> 546 | H19: Vial | I19: Camino | K19: Vial | L19: Camino
C20: Iluminancia Media | D20: Em | E20: lux | F20: 12 | H20: =IF(F20>C41,IF(F20>C40,IF(F20>C39,IF(F20>C38,IF(F20>C37,IF(F20>C36,D36,D36+((F20-C36)*(D37-D36)/(C37-C36))),D37+((F20-C37)*(D38-D37)/(C38-C37))),D38+((F20-C38)*(D39-D38)/(C39-C38))),D39+((F20-C39)*(D40-D39)/(C40-C39))),D40+((F20-C40)*(D41-D40)/(C41-C40))),D41) -> 31.8 | I20: =IF(F20>C51,IF(F20>C50,IF(F20>C49,IF(F20>C48,IF(F20>C47,D47,D47+((F20-C47)*(D48-D47)/(C48-C47))),D48+((F20-C48)*(D49-D48)/(C49-C48))),D49+((F20-C49)*(D50-D49)/(C50-C49))),D50+((F20-C50)*(D51-D50)/(C51-C50))),D51) -> 16.4 | K20: =IF(F20>I41,IF(F20>I40,IF(F20>I39,IF(F20>I38,IF(F20>I37,IF(F20>I36,J36,J36+((F20-I36)*(J37-J36)/(I37-I36))),J37+((F20-I37)*(J38-J37)/(I38-I37))),J38+((F20-I38)*(J39-J38)/(I39-I38))),J39+((F20-I39)*(J40-J39)/(I40-I39))),J40+((F20-I40)*(J41-J40)/(I41-I40))),J41) -> 39.2 | L20: =IF(F20>I51,IF(F20>I50,IF(F20>I49,IF(F20>I48,IF(F20>I47,J47,J47+((F20-I47)*(J48-J47)/(I48-I47))),J48+((F20-I48)*(J49-J48)/(I49-I48))),J49+((F20-I49)*(J50-J49)/(I50-I49))),J50+((F20-I50)*(J51-J50)/(I51-I50))),J51) -> 26.4 | N20: =IF('Sección 2.3'!$D$10>='Sección 2.3'!M37,'Sección 2.3'!N37,IF(AND('Sección 2.3'!$D$10>='Sección 2.3'!M38,'Sección 2.3'!$D$10<'Sección 2.3'!M37),'Sección 2.3'!N38,IF(AND('Sección 2.3'!$D$10>='Sección 2.3'!M39,'Sección 2.3'!$D$10<'Sección 2.3'!M38),'Sección 2.3'!N39,IF(AND('Sección 2.3'!$D$10>='Sección 2.3'!M40,'Sección 2.3'!$D$10<'Sección 2.3'!M39),'Sección 2.3'!N40,IF(AND('Sección 2.3'!$D$10>='Sección 2.3'!M41,'Sección 2.3'!$D$10<'Sección 2.3'!M40),'Sección 2.3'!N41,IF(AND('Sección 2.3'!$D$10>='Sección 2.3'!M42,'Sección 2.3'!$D$10<'Sección 2.3'!M41),'Sección 2.3'!N42,N43)))))) -> A
C21: Potencia Instalada | D21: P | E21: W | F21: =SUM(F22:F23) -> 122 | G21: (autocalculado)
C22: Potencia lámpara | D22: Pl | E22: W | F22: =2*61 -> 122 | H22: POTENCIA UNIT MÁXIMA
C23: Potencia equipo | D23: Pe | E23: W | F23: 0 | H23: Vial | I23: Camino
C24: Factor de mantenimiento | D24: Fm | E24: - | F24: 0.8 | H24: =IF(F20>F41,IF(F20>F40,IF(F20>F39,IF(F20>F38,IF(F20>F37,IF(F20>F36,G36,G36+((F20-F36)*(G37-G36)/(F37-F36))),G37+((F20-F37)*(G38-G37)/(F38-F37))),G38+((F20-F38)*(G39-G38)/(F39-F38))),G39+((F20-F39)*(G40-G39)/(F40-F39))),G40+((F20-F40)*(G41-G40)/(F41-F40))),G41) -> 0.372 | I24: =IF(F20>F51,IF(F20>F50,IF(F20>F49,IF(F20>F48,IF(F20>F47,G47,G47+((F20-F47)*(G48-G47)/(F48-F47))),G48+((F20-F48)*(G49-G48)/(F49-F48))),G49+((F20-F49)*(G50-G49)/(F50-F49))),G50+((F20-F50)*(G51-G50)/(F51-F50))),G51) -> 0.73
C25: Eficiencia lámpara | D25: el | E25: lum/W | F25: =F26/F21 -> 163.93443 | G25: (autocalculado)
C26: Flujo lámpara | D26: Fl | E26: lum | F26: =10000*2 -> 20000
C27: Situación Proyecto | F27: B1
C28: Clase de Alumbrado | F28: ME2
C29: Vial/Camino | E29: V/C | F29: V
C30: Potencia unitaria (W/m²) | F30: =F21/F19 -> 0.22344322
C33: Tabla 1 - Eficiencia Viales | F33: Tabla 1 - Potencia unitaria | I33: Tabla 3 - Eficiencia referencia Viales | M33: Tabla 4 - Calificación Energética
C35: Em(lux) | D35: emínima | F35: Em(lux) | G35: emínima | I35: Em(lux) | J35: emínima | M35: I. Eficiencia | N35: Calificación
C36: 30 | D36: 36 | F36: 30 | G36: 0.83 | I36: 30 | J36: 68
C37: 25 | D37: 35 | F37: 25 | G37: 0.71 | I37: 25 | J37: 60 | M37: 1.1 | N37: A
C38: 20 | D38: 34 | F38: 20 | G38: 0.59 | I38: 20 | J38: 52 | M38: 0.92 | N38: B
C39: 15 | D39: 33 | F39: 15 | G39: 0.45 | I39: 15 | J39: 44 | M39: 0.74 | N39: C
C40: 10 | D40: 31 | F40: 10 | G40: 0.32 | I40: 10 | J40: 36 | M40: 0.56 | N40: D
C41: 7.5 | D41: 29 | F41: 7.5 | G41: 0.26 | I41: 7.5 | J41: 28 | M41: 0.38 | N41: E
M42: 0.2 | N42: F
N43: G
C44: Tabla 2 - Eficiencia Caminos | F44: Tabla 1 - Potencia unitaria | I44: Tabla 3 - Eficiencia referencia caminos
C46: Em(lux) | D46: emínima | F46: Em(lux) | G46: emínima | I46: Em(lux) | J46: emínima
C47: 20 | D47: 18 | F47: 20 | G47: 1.11 | I47: 20 | J47: 36
C48: 15 | D48: 17 | F48: 15 | G48: 0.88 | I48: 15 | J48: 30
...

Sheet Sección 2.4
C2: SECCIÓN 2.4
C4: SITUACIÓN DE PROYECTO | D4: ='Sección 2.4'!$F$27 -> B1
C5: CLASE DE ALUMBRADO | D5: ='Sección 2.4'!$F$28 -> ME2
C6: VALOR DE EFICIENCIA ENERGÉTICA = | D6: =('Sección 2.4'!F19*'Sección 2.4'!F20)/'Sección 2.4'!F21 -> 51.739438
C7: VALOR DE EFICIENCIA ENERGÉTICA MÍNIMA = | D7: =IF('Sección 2.4'!F29="v",'Sección 2.4'!H20,'Sección 2.4'!I20) -> 30.944
C8: EFICIENCIA>EFICIENCIA MÍNIMA | D8: =IF(D7<=D6,"CUMPLE","NO CUMPLE") -> CUMPLE
C9: EFICIENCIA ENERGÉTICA DE REFERENCIA | D9: =IF('Sección 2.4'!F29="v",'Sección 2.4'!K20,'Sección 2.4'!L20) -> 35.776
C10: INDICE DE EFICIENCIA ENERGÉTICA = | D10: =D6/D9 -> 1.4462052
C11: CLASIFICACIÓN ENERGÉTICA DE LA INSTALACIÓN = | D11: ='Sección 2.4'!N20 -> A
C12: FACTOR DE UTILIZACIÓN = | D12: =D6/(F25*F24) -> 0.40846924
C13: POTENCIA UNITARIA<POTENCIA UNITARIA MÁXIMA | D13: =IF(F30<=H24,"CUMPLE","NO CUMPLE") -> CUMPLE
C15: CALCULOS
C17: Dato | D17: Referencia | E17: Ud | F17: Valor
H18: EFICIENCIA MÍNIMA | K18: EFICIENCIA REFERENCIA | N18: CALIFICACIÓN ENERGÉTICA
C19: Superficie | D19: S | E19: m2 | F19: =12.2*20.5 -> 250.1 | H19: Vial | I19: Camino | K19: Vial | L19: Camino
C20: Iluminancia Media | D20: Em | E20: lux | F20: 9.93 | H20: =IF(F20>C41,IF(F20>C40,IF(F20>C39,IF(F20>C38,IF(F20>C37,IF(F20>C36,D36,D36+((F20-C36)*(D37-D36)/(C37-C36))),D37+((F20-C37)*(D38-D37)/(C38-C37))),D38+((F20-C38)*(D39-D38)/(C39-C38))),D39+((F20-C39)*(D40-D39)/(C40-C39))),D40+((F20-C40)*(D41-D40)/(C41-C40))),D41) -> 30.944 | I20: =IF(F20>C51,IF(F20>C50,IF(F20>C49,IF(F20>C48,IF(F20>C47,D47,D47+((F20-C47)*(D48-D47)/(C48-C47))),D48+((F20-C48)*(D49-D48)/(C49-C48))),D49+((F20-C49)*(D50-D49)/(C50-C49))),D50+((F20-C50)*(D51-D50)/(C51-C50))),D51) -> 15.944 | K20: =IF(F20>I41,IF(F20>I40,IF(F20>I39,IF(F20>I38,IF(F20>I37,IF(F20>I36,J36,J36+((F20-I36)*(J37-J36)/(I37-I36))),J37+((F20-I37)*(J38-J37)/(I38-I37))),J38+((F20-I38)*(J39-J38)/(I39-I38))),J39+((F20-I39)*(J40-J39)/(I40-I39))),J40+((F20-I40)*(J41-J40)/(I41-I40))),J41) -> 35.776 | L20: =IF(F20>I51,IF(F20>I50,IF(F20>I49,IF(F20>I48,IF(F20>I47,J47,J47+((F20-I47)*(J48-J47)/(I48-I47))),J48+((F20-I48)*(J49-J48)/(I49-I48))),J49+((F20-I49)*(J50-J49)/(I50-I49))),J50+((F20-I50)*(J51-J50)/(I51-I50))),J51) -> 23.832 | N20: =IF('Sección 2.4'!$D$10>='Sección 2.4'!M37,'Sección 2.4'!N37,IF(AND('Sección 2.4'!$D$10>='Sección 2.4'!M38,'Sección 2.4'!$D$10<'Sección 2.4'!M37),'Sección 2.4'!N38,IF(AND('Sección 2.4'!$D$10>='Sección 2.4'!M39,'Sección 2.4'!$D$10<'Sección 2.4'!M38),'Sección 2.4'!N39,IF(AND('Sección 2.4'!$D$10>='Sección 2.4'!M40,'Sección 2.4'!$D$10<'Sección 2.4'!M39),'Sección 2.4'!N40,IF(AND('Sección 2.4'!$D$10>='Sección 2.4'!M41,'Sección 2.4'!$D$10<'Sección 2.4'!M40),'Sección 2.4'!N41,IF(AND('Sección 2.4'!$D$10>='Sección 2.4'!M42,'Sección 2.4'!$D$10<'Sección 2.4'!M41),'Sección 2.4'!N42,N43)))))) -> A
C21: Potencia Instalada | D21: P | E21: W | F21: =SUM(F22:F23) -> 48 | G21: (autocalculado)
C22: Potencia lámpara | D22: Pl | E22: W | F22: =48 -> 48 | H22: POTENCIA UNIT MÁXIMA
C23: Potencia equipo | D23: Pe | E23: W | F23: 0 | H23: Vial | I23: Camino
C24: Factor de mantenimiento | D24: Fm | E24: - | F24: 0.8 | H24: =IF(F20>F41,IF(F20>F40,IF(F20>F39,IF(F20>F38,IF(F20>F37,IF(F20>F36,G36,G36+((F20-F36)*(G37-G36)/(F37-F36))),G37+((F20-F37)*(G38-G37)/(F38-F37))),G38+((F20-F38)*(G39-G38)/(F39-F38))),G39+((F20-F39)*(G40-G39)/(F40-F39))),G40+((F20-F40)*(G41-G40)/(F41-F40))),G41) -> 0.31832 | I24: =IF(F20>F51,IF(F20>F50,IF(F20>F49,IF(F20>F48,IF(F20>F47,G47,G47+((F20-F47)*(G48-G47)/(F48-F47))),G48+((F20-F48)*(G49-G48)/(F49-F48))),G49+((F20-F49)*(G50-G49)/(F50-F49))),G50+((F20-F50)*(G51-G50)/(F51-F50))),G51) -> 0.6272
C25: Eficiencia lámpara | D25: el | E25: lum/W | F25: =F26/F21 -> 158.33333 | G25: (autocalculado)
C26: Flujo lámpara | D26: Fl | E26: lum | F26: =7600 -> 7600
C27: Situación Proyecto | F27: B1
C28: Clase de Alumbrado | F28: ME2
C29: Vial/Camino | E29: V/C | F29: V
C30: Potencia unitaria (W/m²) | F30: =F21/F19 -> 0.19192323
C33: Tabla 1 - Eficiencia Viales | F33: Tabla 1 - Potencia unitaria | I33: Tabla 3 - Eficiencia referencia Viales | M33: Tabla 4 - Calificación Energética
C35: Em(lux) | D35: emínima | F35: Em(lux) | G35: emínima | I35: Em(lux) | J35: emínima | M35: I. Eficiencia | N35: Calificación
C36: 30 | D36: 36 | F36: 30 | G36: 0.83 | I36: 30 | J36: 68
C37: 25 | D37: 35 | F37: 25 | G37: 0.71 | I37: 25 | J37: 60 | M37: 1.1 | N37: A
C38: 20 | D38: 34 | F38: 20 | G38: 0.59 | I38: 20 | J38: 52 | M38: 0.92 | N38: B
C39: 15 | D39: 33 | F39: 15 | G39: 0.45 | I39: 15 | J39: 44 | M39: 0.74 | N39: C
C40: 10 | D40: 31 | F40: 10 | G40: 0.32 | I40: 10 | J40: 36 | M40: 0.56 | N40: D
C41: 7.5 | D41: 29 | F41: 7.5 | G41: 0.26 | I41: 7.5 | J41: 28 | M41: 0.38 | N41: E
M42: 0.2 | N42: F
N43: G
C44: Tabla 2 - Eficiencia Caminos | F44: Tabla 1 - Potencia unitaria | I44: Tabla 3 - Eficiencia referencia caminos
C46: Em(lux) | D46: emínima | F46: Em(lux) | G46: emínima | I46: Em(lux) | J46: emínima
C47: 20 | D47: 18 | F47: 20 | G47: 1.11 | I47: 20 | J47: 36
C48: 15 | D48: 17 | F48: 15 | G48: 0.88 | I48: 15 | J48: 30
...

Sheet Rotonda puente
C2: ROTONDA PUENTE
C4: SITUACIÓN DE PROYECTO | D4: ='Rotonda puente'!$F$27 -> B1
C5: CLASE DE ALUMBRADO | D5: ='Rotonda puente'!$F$28 -> ME2
C6: VALOR DE EFICIENCIA ENERGÉTICA = | D6: =('Rotonda puente'!F19*'Rotonda puente'!F20)/'Rotonda puente'!F21 -> 63.182947
C7: VALOR DE EFICIENCIA ENERGÉTICA MÍNIMA = | D7: =IF('Rotonda puente'!F29="v",'Rotonda puente'!H20,'Rotonda puente'!I20) -> 36
C8: EFICIENCIA>EFICIENCIA MÍNIMA | D8: =IF(D7<=D6,"CUMPLE","NO CUMPLE") -> CUMPLE
C9: EFICIENCIA ENERGÉTICA DE REFERENCIA | D9: =IF('Rotonda puente'!F29="v",'Rotonda puente'!K20,'Rotonda puente'!L20) -> 68
C10: INDICE DE EFICIENCIA ENERGÉTICA = | D10: =D6/D9 -> 0.92916099
C11: CLASIFICACIÓN ENERGÉTICA DE LA INSTALACIÓN = | D11: ='Rotonda puente'!N20 -> B
C12: FACTOR DE UTILIZACIÓN = | D12: =D6/(F25*F24) -> 0.48703522
C13: POTENCIA UNITARIA<POTENCIA UNITARIA MÁXIMA | D13: =IF(F30<=H24,"CUMPLE","NO CUMPLE") -> CUMPLE
C15: CALCULOS
C17: Dato | D17: Referencia | E17: Ud | F17: Valor
H18: EFICIENCIA MÍNIMA | K18: EFICIENCIA REFERENCIA | N18: CALIFICACIÓN ENERGÉTICA
C19: Superficie | D19: S | E19: m2 | F19: =PI()*((25.3*25.3)-(12*12)) -> 1558.5127 | H19: Vial | I19: Camino | K19: Vial | L19: Camino
C20: Iluminancia Media | D20: Em | E20: lux | F20: 30 | H20: =IF(F20>C41,IF(F20>C40,IF(F20>C39,IF(F20>C38,IF(F20>C37,IF(F20>C36,D36,D36+((F20-C36)*(D37-D36)/(C37-C36))),D37+((F20-C37)*(D38-D37)/(C38-C37))),D38+((F20-C38)*(D39-D38)/(C39-C38))),D39+((F20-C39)*(D40-D39)/(C40-C39))),D40+((F20-C40)*(D41-D40)/(C41-C40))),D41) -> 36 | I20: =IF(F20>C51,IF(F20>C50,IF(F20>C49,IF(F20>C48,IF(F20>C47,D47,D47+((F20-C47)*(D48-D47)/(C48-C47))),D48+((F20-C48)*(D49-D48)/(C49-C48))),D49+((F20-C49)*(D50-D49)/(C50-C49))),D50+((F20-C50)*(D51-D50)/(C51-C50))),D51) -> 18 | K20: =IF(F20>I41,IF(F20>I40,IF(F20>I39,IF(F20>I38,IF(F20>I37,IF(F20>I36,J36,J36+((F20-I36)*(J37-J36)/(I37-I36))),J37+((F20-I37)*(J38-J37)/(I38-I37))),J38+((F20-I38)*(J39-J38)/(I39-I38))),J39+((F20-I39)*(J40-J39)/(I40-I39))),J40+((F20-I40)*(J41-J40)/(I41-I40))),J41) -> 68 | L20: =IF(F20>I51,IF(F20>I50,IF(F20>I49,IF(F20>I48,IF(F20>I47,J47,J47+((F20-I47)*(J48-J47)/(I48-I47))),J48+((F20-I48)*(J49-J48)/(I49-I48))),J49+((F20-I49)*(J50-J49)/(I50-I49))),J50+((F20-I50)*(J51-J50)/(I51-I50))),J51) -> 36 | N20: =IF('Rotonda puente'!$D$10>='Rotonda puente'!M37,'Rotonda puente'!N37,IF(AND('Rotonda puente'!$D$10>='Rotonda puente'!M38,'Rotonda puente'!$D$10<'Rotonda puente'!M37),'Rotonda puente'!N38,IF(AND('Rotonda puente'!$D$10>='Rotonda puente'!M39,'Rotonda puente'!$D$10<'Rotonda puente'!M38),'Rotonda puente'!N39,IF(AND('Rotonda puente'!$D$10>='Rotonda puente'!M40,'Rotonda puente'!$D$10<'Rotonda puente'!M39),'Rotonda puente'!N40,IF(AND('Rotonda puente'!$D$10>='Rotonda puente'!M41,'Rotonda puente'!$D$10<'Rotonda puente'!M40),'Rotonda puente'!N41,IF(AND('Rotonda puente'!$D$10>='Rotonda puente'!M42,'Rotonda puente'!$D$10<'Rotonda puente'!M41),'Rotonda puente'!N42,N43)))))) -> B
C21: Potencia Instalada | D21: P | E21: W | F21: =SUM(F22:F23) -> 740 | G21: (autocalculado)
C22: Potencia lámpara | D22: Pl | E22: W | F22: =10*74 -> 740 | H22: POTENCIA UNIT MÁXIMA
C23: Potencia equipo | D23: Pe | E23: W | F23: 0 | H23: Vial | I23: Camino
C24: Factor de mantenimiento | D24: Fm | E24: - | F24: 0.8 | H24: =IF(F20>F41,IF(F20>F40,IF(F20>F39,IF(F20>F38,IF(F20>F37,IF(F20>F36,G36,G36+((F20-F36)*(G37-G36)/(F37-F36))),G37+((F20-F37)*(G38-G37)/(F38-F37))),G38+((F20-F38)*(G39-G38)/(F39-F38))),G39+((F20-F39)*(G40-G39)/(F40-F39))),G40+((F20-F40)*(G41-G40)/(F41-F40))),G41) -> 0.83 | I24: =IF(F20>F51,IF(F20>F50,IF(F20>F49,IF(F20>F48,IF(F20>F47,G47,G47+((F20-F47)*(G48-G47)/(F48-F47))),G48+((F20-F48)*(G49-G48)/(F49-F48))),G49+((F20-F49)*(G50-G49)/(F50-F49))),G50+((F20-F50)*(G51-G50)/(F51-F50))),G51) -> 1.11
C25: Eficiencia lámpara | D25: el | E25: lum/W | F25: =F26/F21 -> 162.16216 | G25: (autocalculado)
C26: Flujo lámpara | D26: Fl | E26: lum | F26: =10*12000 -> 120000
C27: Situación Proyecto | F27: B1
C28: Clase de Alumbrado | F28: ME2
C29: Vial/Camino | E29: V/C | F29: V
C30: Potencia unitaria (W/m²) | F30: =F21/F19 -> 0.47481166
C33: Tabla 1 - Eficiencia Viales | F33: Tabla 1 - Potencia unitaria | I33: Tabla 3 - Eficiencia referencia Viales | M33: Tabla 4 - Calificación Energética
C35: Em(lux) | D35: emínima | F35: Em(lux) | G35: emínima | I35: Em(lux) | J35: emínima | M35: I. Eficiencia | N35: Calificación
C36: 30 | D36: 36 | F36: 30 | G36: 0.83 | I36: 30 | J36: 68
C37: 25 | D37: 35 | F37: 25 | G37: 0.71 | I37: 25 | J37: 60 | M37: 1.1 | N37: A
C38: 20 | D38: 34 | F38: 20 | G38: 0.59 | I38: 20 | J38: 52 | M38: 0.92 | N38: B
C39: 15 | D39: 33 | F39: 15 | G39: 0.45 | I39: 15 | J39: 44 | M39: 0.74 | N39: C
C40: 10 | D40: 31 | F40: 10 | G40: 0.32 | I40: 10 | J40: 36 | M40: 0.56 | N40: D
C41: 7.5 | D41: 29 | F41: 7.5 | G41: 0.26 | I41: 7.5 | J41: 28 | M41: 0.38 | N41: E
M42: 0.2 | N42: F
N43: G
C44: Tabla 2 - Eficiencia Caminos | F44: Tabla 1 - Potencia unitaria | I44: Tabla 3 - Eficiencia referencia caminos
C46: Em(lux) | D46: emínima | F46: Em(lux) | G46: emínima | I46: Em(lux) | J46: emínima
C47: 20 | D47: 18 | F47: 20 | G47: 1.11 | I47: 20 | J47: 36
C48: 15 | D48: 17 | F48: 15 | G48: 0.88 | I48: 15 | J48: 30
...

Sheet Rotonda Guadalmar
C2: ROTONDA GUADALMAR
C4: SITUACIÓN DE PROYECTO | D4: ='Rotonda Guadalmar'!$F$27 -> B1
C5: CLASE DE ALUMBRADO | D5: ='Rotonda Guadalmar'!$F$28 -> ME2
C6: VALOR DE EFICIENCIA ENERGÉTICA = | D6: =('Rotonda Guadalmar'!F19*'Rotonda Guadalmar'!F20)/'Rotonda Guadalmar'!F21 -> 48.859195
C7: VALOR DE EFICIENCIA ENERGÉTICA MÍNIMA = | D7: =IF('Rotonda Guadalmar'!F29="v",'Rotonda Guadalmar'!H20,'Rotonda Guadalmar'!I20) -> 36
C8: EFICIENCIA>EFICIENCIA MÍNIMA | D8: =IF(D7<=D6,"CUMPLE","NO CUMPLE") -> CUMPLE
C9: EFICIENCIA ENERGÉTICA DE REFERENCIA | D9: =IF('Rotonda Guadalmar'!F29="v",'Rotonda Guadalmar'!K20,'Rotonda Guadalmar'!L20) -> 68
C10: INDICE DE EFICIENCIA ENERGÉTICA = | D10: =D6/D9 -> 0.71851758
C11: CLASIFICACIÓN ENERGÉTICA DE LA INSTALACIÓN = | D11: ='Rotonda Guadalmar'!N20 -> D
C12: FACTOR DE UTILIZACIÓN = | D12: =D6/(F25*F24) -> 0.37662296
C13: POTENCIA UNITARIA<POTENCIA UNITARIA MÁXIMA | D13: =IF(F30<=H24,"CUMPLE","NO CUMPLE") -> CUMPLE
C15: CALCULOS
C17: Dato | D17: Referencia | E17: Ud | F17: Valor
H18: EFICIENCIA MÍNIMA | K18: EFICIENCIA REFERENCIA | N18: CALIFICACIÓN ENERGÉTICA
C19: Superficie | D19: S | E19: m2 | F19: =PI()*((21*21)-(12*12)) -> 933.05302 | H19: Vial | I19: Camino | K19: Vial | L19: Camino
C20: Iluminancia Media | D20: Em | E20: lux | F20: 31 | H20: =IF(F20>C41,IF(F20>C40,IF(F20>C39,IF(F20>C38,IF(F20>C37,IF(F20>C36,D36,D36+((F20-C36)*(D37-D36)/(C37-C36))),D37+((F20-C37)*(D38-D37)/(C38-C37))),D38+((F20-C38)*(D39-D38)/(C39-C38))),D39+((F20-C39)*(D40-D39)/(C40-C39))),D40+((F20-C40)*(D41-D40)/(C41-C40))),D41) -> 36 | I20: =IF(F20>C51,IF(F20>C50,IF(F20>C49,IF(F20>C48,IF(F20>C47,D47,D47+((F20-C47)*(D48-D47)/(C48-C47))),D48+((F20-C48)*(D49-D48)/(C49-C48))),D49+((F20-C49)*(D50-D49)/(C50-C49))),D50+((F20-C50)*(D51-D50)/(C51-C50))),D51) -> 18 | K20: =IF(F20>I41,IF(F20>I40,IF(F20>I39,IF(F20>I38,IF(F20>I37,IF(F20>I36,J36,J36+((F20-I36)*(J37-J36)/(I37-I36))),J37+((F20-I37)*(J38-J37)/(I38-I37))),J38+((F20-I38)*(J39-J38)/(I39-I38))),J39+((F20-I39)*(J40-J39)/(I40-I39))),J40+((F20-I40)*(J41-J40)/(I41-I40))),J41) -> 68 | L20: =IF(F20>I51,IF(F20>I50,IF(F20>I49,IF(F20>I48,IF(F20>I47,J47,J47+((F20-I47)*(J48-J47)/(I48-I47))),J48+((F20-I48)*(J49-J48)/(I49-I48))),J49+((F20-I49)*(J50-J49)/(I50-I49))),J50+((F20-I50)*(J51-J50)/(I51-I50))),J51) -> 36 | N20: =IF('Rotonda Guadalmar'!$D$10>='Rotonda Guadalmar'!M37,'Rotonda Guadalmar'!N37,IF(AND('Rotonda Guadalmar'!$D$10>='Rotonda Guadalmar'!M38,'Rotonda Guadalmar'!$D$10<'Rotonda Guadalmar'!M37),'Rotonda Guadalmar'!N38,IF(AND('Rotonda Guadalmar'!$D$10>='Rotonda Guadalmar'!M39,'Rotonda Guadalmar'!$D$10<'Rotonda Guadalmar'!M38),'Rotonda Guadalmar'!N39,IF(AND('Rotonda Guadalmar'!$D$10>='Rotonda Guadalmar'!M40,'Rotonda Guadalmar'!$D$10<'Rotonda Guadalmar'!M39),'Rotonda Guadalmar'!N40,IF(AND('Rotonda Guadalmar'!$D$10>='Rotonda Guadalmar'!M41,'Rotonda Guadalmar'!$D$10<'Rotonda Guadalmar'!M40),'Rotonda Guadalmar'!N41,IF(AND('Rotonda Guadalmar'!$D$10>='Rotonda Guadalmar'!M42,'Rotonda Guadalmar'!$D$10<'Rotonda Guadalmar'!M41),'Rotonda Guadalmar'!N42,N43)))))) -> D
C21: Potencia Instalada | D21: P | E21: W | F21: =SUM(F22:F23) -> 592 | G21: (autocalculado)
C22: Potencia lámpara | D22: Pl | E22: W | F22: =8*74 -> 592 | H22: POTENCIA UNIT MÁXIMA
C23: Potencia equipo | D23: Pe | E23: W | F23: 0 | H23: Vial | I23: Camino
C24: Factor de mantenimiento | D24: Fm | E24: - | F24: 0.8 | H24: =IF(F20>F41,IF(F20>F40,IF(F20>F39,IF(F20>F38,IF(F20>F37,IF(F20>F36,G36,G36+((F20-F36)*(G37-G36)/(F37-F36))),G37+((F20-F37)*(G38-G37)/(F38-F37))),G38+((F20-F38)*(G39-G38)/(F39-F38))),G39+((F20-F39)*(G40-G39)/(F40-F39))),G40+((F20-F40)*(G41-G40)/(F41-F40))),G41) -> 0.83 | I24: =IF(F20>F51,IF(F20>F50,IF(F20>F49,IF(F20>F48,IF(F20>F47,G47,G47+((F20-F47)*(G48-G47)/(F48-F47))),G48+((F20-F48)*(G49-G48)/(F49-F48))),G49+((F20-F49)*(G50-G49)/(F50-F49))),G50+((F20-F50)*(G51-G50)/(F51-F50))),G51) -> 1.11
C25: Eficiencia lámpara | D25: el | E25: lum/W | F25: =F26/F21 -> 162.16216 | G25: (autocalculado)
C26: Flujo lámpara | D26: Fl | E26: lum | F26: =8*12000 -> 96000
C27: Situación Proyecto | F27: B1
C28: Clase de Alumbrado | F28: ME2
C29: Vial/Camino | E29: V/C | F29: V
C30: Potencia unitaria (W/m²) | F30: =F21/F19 -> 0.63447627
C33: Tabla 1 - Eficiencia Viales | F33: Tabla 1 - Potencia unitaria | I33: Tabla 3 - Eficiencia referencia Viales | M33: Tabla 4 - Calificación Energética
C35: Em(lux) | D35: emínima | F35: Em(lux) | G35: emínima | I35: Em(lux) | J35: emínima | M35: I. Eficiencia | N35: Calificación
C36: 30 | D36: 36 | F36: 30 | G36: 0.83 | I36: 30 | J36: 68
C37: 25 | D37: 35 | F37: 25 | G37: 0.71 | I37: 25 | J37: 60 | M37: 1.1 | N37: A
C38: 20 | D38: 34 | F38: 20 | G38: 0.59 | I38: 20 | J38: 52 | M38: 0.92 | N38: B
C39: 15 | D39: 33 | F39: 15 | G39: 0.45 | I39: 15 | J39: 44 | M39: 0.74 | N39: C
C40: 10 | D40: 31 | F40: 10 | G40: 0.32 | I40: 10 | J40: 36 | M40: 0.56 | N40: D
C41: 7.5 | D41: 29 | F41: 7.5 | G41: 0.26 | I41: 7.5 | J41: 28 | M41: 0.38 | N41: E
M42: 0.2 | N42: F
N43: G
C44: Tabla 2 - Eficiencia Caminos | F44: Tabla 1 - Potencia unitaria | I44: Tabla 3 - Eficiencia referencia caminos
C46: Em(lux) | D46: emínima | F46: Em(lux) | G46: emínima | I46: Em(lux) | J46: emínima
C47: 20 | D47: 18 | F47: 20 | G47: 1.11 | I47: 20 | J47: 36
C48: 15 | D48: 17 | F48: 15 | G48: 0.88 | I48: 15 | J48: 30
...

Sheet Vial mixto
C2: RESULTADO VIAL RV.01
C4: SITUACIÓN DE PROYECTO | D4: ='Vial mixto'!$F$27 -> B1
C5: CLASE DE ALUMBRADO | D5: ='Vial mixto'!$F$28 -> ME3c
C6: VALOR DE EFICIENCIA ENERGÉTICA = | D6: =('Vial mixto'!F19*'Vial mixto'!F20)/'Vial mixto'!F21 -> 38.333333
C7: VALOR DE EFICIENCIA ENERGÉTICA MÍNIMA = | D7: =IF('Vial mixto'!F29="v",'Vial mixto'!H20,'Vial mixto'!I20) -> 34.6
C8: EFICIENCIA>EFICIENCIA MÍNIMA | D8: =IF(D7<=D6,"CUMPLE","NO CUMPLE") -> CUMPLE
C9: EFICIENCIA ENERGÉTICA DE REFERENCIA | D9: =IF('Vial mixto'!F29="v",'Vial mixto'!K20,'Vial mixto'!L20) -> 56.8
C10: INDICE DE EFICIENCIA ENERGÉTICA = | D10: =D6/D9 -> 0.67488263
C11: CLASIFICACIÓN ENERGÉTICA DE LA INSTALACIÓN = | D11: ='Vial mixto'!N20 -> D
C12: FACTOR DE UTILIZACIÓN = | D12: =D6/(F25*F24) -> 0.34582999
C13: POTENCIA UNITARIA<POTENCIA UNITARIA MÁXIMA | D13: =IF(F30<=H24,"CUMPLE","NO CUMPLE") -> CUMPLE
C15: CALCULOS
C17: Dato | D17: Referencia | E17: Ud | F17: Valor
H18: EFICIENCIA MÍNIMA | K18: EFICIENCIA REFERENCIA | N18: CALIFICACIÓN ENERGÉTICA
C19: Superficie | D19: S | E19: m2 | F19: =18*5 -> 90 | H19: Vial | I19: Camino | K19: Vial | L19: Camino
C20: Iluminancia Media | D20: Em | E20: lux | F20: 23 | H20: =IF(F20>C41,IF(F20>C40,IF(F20>C39,IF(F20>C38,IF(F20>C37,IF(F20>C36,D36,D36+((F20-C36)*(D37-D36)/(C37-C36))),D37+((F20-C37)*(D38-D37)/(C38-C37))),D38+((F20-C38)*(D39-D38)/(C39-C38))),D39+((F20-C39)*(D40-D39)/(C40-C39))),D40+((F20-C40)*(D41-D40)/(C41-C40))),D41) -> 34.6 | I20: =IF(F20>C51,IF(F20>C50,IF(F20>C49,IF(F20>C48,IF(F20>C47,D47,D47+((F20-C47)*(D48-D47)/(C48-C47))),D48+((F20-C48)*(D49-D48)/(C49-C48))),D49+((F20-C49)*(D50-D49)/(C50-C49))),D50+((F20-C50)*(D51-D50)/(C51-C50))),D51) -> 18 | K20: =IF(F20>I41,IF(F20>I40,IF(F20>I39,IF(F20>I38,IF(F20>I37,IF(F20>I36,J36,J36+((F20-I36)*(J37-J36)/(I37-I36))),J37+((F20-I37)*(J38-J37)/(I38-I37))),J38+((F20-I38)*(J39-J38)/(I39-I38))),J39+((F20-I39)*(J40-J39)/(I40-I39))),J40+((F20-I40)*(J41-J40)/(I41-I40))),J41) -> 56.8 | L20: =IF(F20>I51,IF(F20>I50,IF(F20>I49,IF(F20>I48,IF(F20>I47,J47,J47+((F20-I47)*(J48-J47)/(I48-I47))),J48+((F20-I48)*(J49-J48)/(I49-I48))),J49+((F20-I49)*(J50-J49)/(I50-I49))),J50+((F20-I50)*(J51-J50)/(I51-I50))),J51) -> 36 | N20: =IF('Vial mixto'!$D$10>='Vial mixto'!M37,'Vial mixto'!N37,IF(AND('Vial mixto'!$D$10>='Vial mixto'!M38,'Vial mixto'!$D$10<'Vial mixto'!M37),'Vial mixto'!N38,IF(AND('Vial mixto'!$D$10>='Vial mixto'!M39,'Vial mixto'!$D$10<'Vial mixto'!M38),'Vial mixto'!N39,IF(AND('Vial mixto'!$D$10>='Vial mixto'!M40,'Vial mixto'!$D$10<'Vial mixto'!M39),'Vial mixto'!N40,IF(AND('Vial mixto'!$D$10>='Vial mixto'!M41,'Vial mixto'!$D$10<'Vial mixto'!M40),'Vial mixto'!N41,IF(AND('Vial mixto'!$D$10>='Vial mixto'!M42,'Vial mixto'!$D$10<'Vial mixto'!M41),'Vial mixto'!N42,N43)))))) -> D
C21: Potencia Instalada | D21: P | E21: W | F21: =SUM(F22:F23) -> 54 | G21: (autocalculado)
C22: Potencia lámpara | D22: Pl | E22: W | F22: =2*27 -> 54 | H22: POTENCIA UNIT MÁXIMA
C23: Potencia equipo | D23: Pe | E23: W | F23: 0 | H23: Vial | I23: Camino
C24: Factor de mantenimiento | D24: Fm | E24: - | F24: 0.8 | H24: =IF(F20>F41,IF(F20>F40,IF(F20>F39,IF(F20>F38,IF(F20>F37,IF(F20>F36,G36,G36+((F20-F36)*(G37-G36)/(F37-F36))),G37+((F20-F37)*(G38-G37)/(F38-F37))),G38+((F20-F38)*(G39-G38)/(F39-F38))),G39+((F20-F39)*(G40-G39)/(F40-F39))),G40+((F20-F40)*(G41-G40)/(F41-F40))),G41) -> 0.662 | I24: =IF(F20>F51,IF(F20>F50,IF(F20>F49,IF(F20>F48,IF(F20>F47,G47,G47+((F20-F47)*(G48-G47)/(F48-F47))),G48+((F20-F48)*(G49-G48)/(F49-F48))),G49+((F20-F49)*(G50-G49)/(F50-F49))),G50+((F20-F50)*(G51-G50)/(F51-F50))),G51) -> 1.11
C25: Eficiencia lámpara | D25: el | E25: lum/W | F25: =F26/F21 -> 138.55556 | G25: (autocalculado)
C26: Flujo lámpara | D26: Fl | E26: lum | F26: =3741*2 -> 7482
C27: Situación Proyecto | F27: B1
C28: Clase de Alumbrado | F28: ME3c
C29: Vial/Camino | E29: V/C | F29: V
C30: Potencia unitaria (W/m²) | F30: =F21/F19 -> 0.6
C33: Tabla 1 - Eficiencia Viales | F33: Tabla 1 - Potencia unitaria | I33: Tabla 3 - Eficiencia referencia Viales | M33: Tabla 4 - Calificación Energética
C35: Em(lux) | D35: emínima | F35: Em(lux) | G35: emínima | I35: Em(lux) | J35: emínima | M35: I. Eficiencia | N35: Calificación
C36: 30 | D36: 36 | F36: 30 | G36: 0.83 | I36: 30 | J36: 68
C37: 25 | D37: 35 | F37: 25 | G37: 0.71 | I37: 25 | J37: 60 | M37: 1.1 | N37: A
C38: 20 | D38: 34 | F38: 20 | G38: 0.59 | I38: 20 | J38: 52 | M38: 0.92 | N38: B
C39: 15 | D39: 33 | F39: 15 | G39: 0.45 | I39: 15 | J39: 44 | M39: 0.74 | N39: C
C40: 10 | D40: 31 | F40: 10 | G40: 0.32 | I40: 10 | J40: 36 | M40: 0.56 | N40: D
C41: 7.5 | D41: 29 | F41: 7.5 | G41: 0.26 | I41: 7.5 | J41: 28 | M41: 0.38 | N41: E
M42: 0.2 | N42: F
N43: G
C44: Tabla 2 - Eficiencia Caminos | F44: Tabla 1 - Potencia unitaria | I44: Tabla 3 - Eficiencia referencia caminos
C46: Em(lux) | D46: emínima | F46: Em(lux) | G46: emínima | I46: Em(lux) | J46: emínima
C47: 20 | D47: 18 | F47: 20 | G47: 1.11 | I47: 20 | J47: 36
C48: 15 | D48: 17 | F48: 15 | G48: 0.88 | I48: 15 | J48: 30
...

Sheet CE-1
C2: RESULTADO VIAL RV.01
C4: SITUACIÓN DE PROYECTO | D4: ='CE-1'!$F$27 -> B1
C5: CLASE DE ALUMBRADO | D5: ='CE-1'!$F$28 -> ME3c
C6: VALOR DE EFICIENCIA ENERGÉTICA = | D6: =('CE-1'!F19*'CE-1'!F20)/'CE-1'!F21 -> 65.333333
C7: VALOR DE EFICIENCIA ENERGÉTICA MÍNIMA = | D7: =IF('CE-1'!F29="v",'CE-1'!H20,'CE-1'!I20) -> 34.2
C8: EFICIENCIA>EFICIENCIA MÍNIMA | D8: =IF(D7<=D6,"CUMPLE","NO CUMPLE") -> CUMPLE
C9: EFICIENCIA ENERGÉTICA DE REFERENCIA | D9: =IF('CE-1'!F29="v",'CE-1'!K20,'CE-1'!L20) -> 53.6
C10: INDICE DE EFICIENCIA ENERGÉTICA = | D10: =D6/D9 -> 1.2189055
C11: CLASIFICACIÓN ENERGÉTICA DE LA INSTALACIÓN = | D11: ='CE-1'!N20 -> A
C12: FACTOR DE UTILIZACIÓN = | D12: =D6/(F25*F24) -> 0.5894146
C13: POTENCIA UNITARIA<POTENCIA UNITARIA MÁXIMA | D13: =IF(F30<=H24,"CUMPLE","NO CUMPLE") -> CUMPLE
C15: CALCULOS
C17: Dato | D17: Referencia | E17: Ud | F17: Valor
H18: EFICIENCIA MÍNIMA | K18: EFICIENCIA REFERENCIA | N18: CALIFICACIÓN ENERGÉTICA
C19: Superficie | D19: S | E19: m2 | F19: =16*10.5 -> 168 | H19: Vial | I19: Camino | K19: Vial | L19: Camino
C20: Iluminancia Media | D20: Em | E20: lux | F20: 21 | H20: =IF(F20>C41,IF(F20>C40,IF(F20>C39,IF(F20>C38,IF(F20>C37,IF(F20>C36,D36,D36+((F20-C36)*(D37-D36)/(C37-C36))),D37+((F20-C37)*(D38-D37)/(C38-C37))),D38+((F20-C38)*(D39-D38)/(C39-C38))),D39+((F20-C39)*(D40-D39)/(C40-C39))),D40+((F20-C40)*(D41-D40)/(C41-C40))),D41) -> 34.2 | I20: =IF(F20>C51,IF(F20>C50,IF(F20>C49,IF(F20>C48,IF(F20>C47,D47,D47+((F20-C47)*(D48-D47)/(C48-C47))),D48+((F20-C48)*(D49-D48)/(C49-C48))),D49+((F20-C49)*(D50-D49)/(C50-C49))),D50+((F20-C50)*(D51-D50)/(C51-C50))),D51) -> 18 | K20: =IF(F20>I41,IF(F20>I40,IF(F20>I39,IF(F20>I38,IF(F20>I37,IF(F20>I36,J36,J36+((F20-I36)*(J37-J36)/(I37-I36))),J37+((F20-I37)*(J38-J37)/(I38-I37))),J38+((F20-I38)*(J39-J38)/(I39-I38))),J39+((F20-I39)*(J40-J39)/(I40-I39))),J40+((F20-I40)*(J41-J40)/(I41-I40))),J41) -> 53.6 | L20: =IF(F20>I51,IF(F20>I50,IF(F20>I49,IF(F20>I48,IF(F20>I47,J47,J47+((F20-I47)*(J48-J47)/(I48-I47))),J48+((F20-I48)*(J49-J48)/(I49-I48))),J49+((F20-I49)*(J50-J49)/(I50-I49))),J50+((F20-I50)*(J51-J50)/(I51-I50))),J51) -> 36 | N20: =IF('CE-1'!$D$10>='CE-1'!M37,'CE-1'!N37,IF(AND('CE-1'!$D$10>='CE-1'!M38,'CE-1'!$D$10<'CE-1'!M37),'CE-1'!N38,IF(AND('CE-1'!$D$10>='CE-1'!M39,'CE-1'!$D$10<'CE-1'!M38),'CE-1'!N39,IF(AND('CE-1'!$D$10>='CE-1'!M40,'CE-1'!$D$10<'CE-1'!M39),'CE-1'!N40,IF(AND('CE-1'!$D$10>='CE-1'!M41,'CE-1'!$D$10<'CE-1'!M40),'CE-1'!N41,IF(AND('CE-1'!$D$10>='CE-1'!M42,'CE-1'!$D$10<'CE-1'!M41),'CE-1'!N42,N43)))))) -> A
C21: Potencia Instalada | D21: P | E21: W | F21: =SUM(F22:F23) -> 54 | G21: (autocalculado)
C22: Potencia lámpara | D22: Pl | E22: W | F22: =2*27 -> 54 | H22: POTENCIA UNIT MÁXIMA
C23: Potencia equipo | D23: Pe | E23: W | F23: 0 | H23: Vial | I23: Camino
C24: Factor de mantenimiento | D24: Fm | E24: - | F24: 0.8 | H24: =IF(F20>F41,IF(F20>F40,IF(F20>F39,IF(F20>F38,IF(F20>F37,IF(F20>F36,G36,G36+((F20-F36)*(G37-G36)/(F37-F36))),G37+((F20-F37)*(G38-G37)/(F38-F37))),G38+((F20-F38)*(G39-G38)/(F39-F38))),G39+((F20-F39)*(G40-G39)/(F40-F39))),G40+((F20-F40)*(G41-G40)/(F41-F40))),G41) -> 0.614 | I24: =IF(F20>F51,IF(F20>F50,IF(F20>F49,IF(F20>F48,IF(F20>F47,G47,G47+((F20-F47)*(G48-G47)/(F48-F47))),G48+((F20-F48)*(G49-G48)/(F49-F48))),G49+((F20-F49)*(G50-G49)/(F50-F49))),G50+((F20-F50)*(G51-G50)/(F51-F50))),G51) -> 1.11
C25: Eficiencia lámpara | D25: el | E25: lum/W | F25: =F26/F21 -> 138.55556 | G25: (autocalculado)
C26: Flujo lámpara | D26: Fl | E26: lum | F26: =3741*2 -> 7482
C27: Situación Proyecto | F27: B1
C28: Clase de Alumbrado | F28: ME3c
C29: Vial/Camino | E29: V/C | F29: V
C30: Potencia unitaria (W/m²) | F30: =F21/F19 -> 0.32142857
C33: Tabla 1 - Eficiencia Viales | F33: Tabla 1 - Potencia unitaria | I33: Tabla 3 - Eficiencia referencia Viales | M33: Tabla 4 - Calificación Energética
