Workbook

Sheet Calculo Hidrológico T 25 - (A)
F1: Actualizado al: | G1: 46079 | L1: COTA | M1: TRAMO | N1: LONG
B2: CALCULO HIDROLOGICO: Mejora Carretera Guadalmar; 535.2 | F2: CUENCA: GUADALMAR | K2: A | L2: 3.503
F3: SUBCUENCA A | K3: B | L3: 3.5 | M3: LAB | N3: 121
B4: METODO RACIONAL | D4: Q=[ I(T,Tc) x C x A x Kt ] / 3,6 | K4: C | L4: 3.341 | M4: LBC | N4: 83
I5: Insertar valores | K5: D | L5: 3.619 | M5: LCD | N5: 123
B6: C=coeficiente medio de escorrentía | F6: Superficie cuenca vertiente (Km2) | G6: =+I6/1000000 -> 0.007441 | I6: =+'Datos 1'!C9 -> 7441 | J6: A.1 | K6: E | L6: 3.537 | M6: LDE | N6: 42
B7: A=area de la cuenca Km2 | F7: Lc=longitud de la cuenca Km | G7: =+I7/1000 -> 0.369 | I7: =+N7 -> 369 | J7: A.2 | N7: =+SUM(N2:N6) -> 369
B8: I=intensidad de precipitación | F8: Jc=pendiente media de la cuenca m/m | G8: =+I8/100 -> 0.0014146341 | I8: =+N8 -> 0.14146341 | J8: A.3 | N8: =100*(ABS(L2-L3)+ABS(L3-L4)+ABS(L4-L5)+ABS(L5-L6))/N7 -> 0.14146341
B9: Kt=coeficiente punta de precipitación ( Km2, m3/sg ) | C9: =1+((G9^1.25)/(G9^1.25+14)) -> 1.0283898 | D9: Kt = 1 + ( tc1,25 / (tc1,25+14)) | E9: I.1 | F9: Tc=tiempo de concentracion | G9: =0.3*(G7^0.76)*(G8^-0.19) -> 0.48914645 | H9: B
F10: (I1/Id) | G10: =C25 -> 9 | H10: C.3
B11: TIEMPO DE CONCENTRACIÓN | F11: Id(mm/h): Pd / 24 | G11: =C21 -> 5.6865 | H11: D.9
F12: I (T, t) (mm/h) | G12: =C19 -> 75.095519 | H12: F.4
B13: Lc=longitud de la cuenca Km | F13: Po Umbral de escorrentia | G13: =C39 -> 3.4417686 | H13: G.15
B14: Jc=pendiente media de la cuenca m/m | F14: C = coeficiente de escorrentia | G14: =C38 -> 0.94387525 | H14: H.2
B15: Tc(h): tiempo de concentración | C15: =G9 -> 0.48914645 | D15: Tc =0,3 x Lc^0,76 x Jc^-0,19 | E15: F.1 | F15: Q(m3/sg) : Caudal resultante | G15: =((C19*C38*C9*G6)/3.6) -> 0.15066598 | H15: I.2
F16: Q(l/sg) : Caudal resultante | G16: =G15*1000 -> 150.66598 | H16: J
B17: INTENSIDAD DE PRECIPITACION
B19: I (T, t) (mm/h): Intensidad de Precipitacion | C19: =C21*C26 -> 75.095519 | D19: I (T,t)= Id x Fint | E19: F.3
B20: Fint max (Fa, Fb)
B21: Id(mm/h): intensidad media diaria Pd/24 | C21: =C22/24 -> 5.6865 | D21: Id = (Pd x Ka) / 24 | E21: Ka =1 si Area cuenca < 1km2 | G21: D.8
B22: Pd(mm): precipitación total diária correspondiente | C22: =C28 -> 136.476 | D22: D.7
B23: al periodo de retorno considerado
B25: (I1/Id):valor por tablas | C25: =+'Datos 2'!L67 -> 9 | D25: Datos 2 | E25: C.2
B26: Fa: | C26: =C25^((3.5287-(2.5287*C15^0.1))) -> 13.20593 | D26: Fa = ( It/Id )^(3,5287-2,5287 t^0,1) | E26: F.2
B27: Fb: informacion de las curvas IDF de pluviografos de la cuenca | D27: No aplicable
B28: Pd(mm/dia) . Máxima Lluvias Diarias | C28: =C32*C33 -> 136.476 | D28: Pd = Yt * P | E28: D.6
B29: Coordenadas U.T.M.
B30: Cv: coeficiente de variación | C30: =+'Datos 2'!B24 -> 0.48 | D30: Datos 2 | E30: D.4
B31: T: periodo de retorno | C31: 25 | D31: No modificar
B32: P: maxima precipitación diaria anual | C32: =+'Datos 2'!V6 -> 68 | D32: Datos 2 | E32: D.3
B33: Yt: cuantíl regional ( por tablas ) | C33: =+'Datos 2'!F24 -> 2.007 | D33: Datos 2 | E33: D.5
B35: COEFICIENTE DE ESCORRENTÍA | D35: C=((Pd/Po)-1)*((Pd/Po)+23)/((Pd/Po)+11)^2
B38: C = coeficiente de escorrentia | C38: =((C22/C39)-1)*((C22/C39)+23)/((C22/C39)+11)^2 -> 0.94387525 | D38: H.1 | K38: Datos 2
B39: Umbral de escorrentia Po | C39: =C40*C41 -> 3.4417686 | D39: Po = Po' β | E39: G.14 | J39: βm= | K39: =+'Datos 2'!M52 -> 2 | L39: G.9
B40: valor inicial Umbral de escorrentia Po' | C40: =+'Datos 1'!L11 -> 1.7879317 | D40: tablas y mapa instruccion | E40: Datos 1 | F40: G.7 | J40: ∆50= | K40: =+'Datos 2'!N52 -> 0.25 | L40: G.10
B41: coeficnte corrector β | C41: =+L41 -> 1.925 | D41: tablas y mapa instruccion | E41: =+"Para T=25  βDT = (βm - ∆50) FT  βDT = "&ROUND(L41,3)&"" -> Para T=25  βDT = (βm - ∆50) FT  βDT = 1,925 | H41: =+"βdt= ("&ROUND(K39, 2)&" - "&ROUND(K40, 2)&") x "&ROUND(K41, 2)&"" -> βdt= (2 - 0,25) x 1,1 | J41: FT25= | K41: =+'Datos 2'!S52 -> 1.1 | L41: =+(K39-K40)*K41 -> 1.925 | M41: G.12
C42: G.13 | K42: G.11

Sheet Datos 1
F1: Actualizado al: | G1: =+'Calculo Hidrológico T 25 - (A)'!G1 -> 46079
A2: =+'Calculo Hidrológico T 25 - (A)'!B2 -> CALCULO HIDROLOGICO: Mejora Carretera Guadalmar; 535.2
C4: A.1
A5: Sub-cuenca | B5: Area vertiente | C5: superficie parcela (m2) | D5: Superficie pavimentada (m2) | F5: Superficie Zona verde (m2)
D6: Interior Parcelas: 60% Superficie pavimentada (m2) | E6: Viales/ST : 100% Superficie pavimentada (m2) | F6: Interior Parcelas: 40% Superficie restante (m2) | G6: Z.V: 100% Superficie Ajardinadas (m2)
D7: - | E7: - | F7: - | G7: =C7 -> 0
D8: =C8*0.6 -> 0 | E8: - | F8: =C8-D8 -> 0 | G8: - | K8: Expresión en el anejo (word)
B9: SUBCUENCA A | C9: =6990+451 -> 7441 | D9: - | E9: 6990 | F9: - | G9: =+M23 -> 451 | K9: =+"Poi = ("&ROUND(D14,1)&" x "&ROUND(D13,3)&") + ("&ROUND(F14,1)&" x "&ROUND(F13,3)&") =" -> Poi = (1 x 0,939) + (14 x 0,061) = | M9: =+L11 -> 1.7879317 | N9: =1*0.939+14*0.061 -> 1.793
B10: Subtotal | D10: =SUM(D7:D9) -> 0 | E10: =SUM(E7:E9) -> 6990 | F10: =SUM(F7:F9) -> 0 | G10: =SUM(G7:G9) -> 451 | H10: ΣÁrea | I10: Po | K10: Po (comprobación)
B11: Total | D11: =D10+E10 -> 6990 | F11: =F10+G10 -> 451 | H11: =D11+F11 -> 7441 | I11: =((D11/H11)*D14)+((F11/H11)*F14) -> 1.7879317 | K11: =(D13*D14)+(F13*F14) -> 1.7879317 | L11: =+K11 -> 1.7879317 | M11: G.6
D12: =+D11*100/SUM($D$11:$G$11) -> 93.938987 | F12: =+F11*100/SUM($D$11:$G$11) -> 6.0610133 | H12: =+D12+F12 -> 100
D13: =+D11/H11 -> 0.93938987 | F13: =+F11/H11 -> 0.060610133 | H13: =+D13+F13 -> 1
D14: =+G67 -> 1 | E14: G.4 | F14: =+G75 -> 14 | G14: G.5 | M14: 14395.11
D15: =+"GRUPO DE SUELO: "&G29&"" -> GRUPO DE SUELO: C | F15: =+"GRUPO DE SUELO: "&G29&"" -> GRUPO DE SUELO: C | L15: Subcuenca Viales: | M15: =+C9 -> 7441
D16: =+B67 -> Redes viarias, ferroviarias y terrenos asociados | F16: =+B75 -> Zonas verdes urbanas | L16: arbolado izquierdo 1
L17: arbolado derecho 1
F18: (T=25) βDT | G18: =+'Calculo Hidrológico T 25 - (A)'!L41 -> 1.925 | L18: arbolado derecho 2
F19: Po | G19: =+L11 -> 1.7879317 | L19: arbolado derecho 3
F20: Po' | G20: =+G18*G19 -> 3.4417686 | L20: arbolado sur-n
L21: arbolado sur-s
L22: Superficie pavimentada (m2) | M22: =+M15-M23 -> 6990
L23: Superficie Ajardinada (m2) | M23: 451
G28: GRUPO DE SUELO:
G29: C | H29: G.1
A57: Código | B57: Uso de suelo | C57: Grupo de suelo A | D57: Grupo de suelo B | E57: Grupo de suelo C | F57: Grupo de suelo D
A58: 11100 | B58: Tejido urbano continuo | C58: 1 | D58: 1 | E58: 1 | F58: 1
A59: 11200 | B59: Tejido urbano discontinuo | C59: 24 | D59: 14 | E59: 8 | F59: 6
A60: 11200 | B60: Urbanizaciones | C60: 24 | D60: 14 | E60: 8 | F60: 6
A61: 11210 | B61: Estructura urbana abierta | C61: 24 | D61: 14 | E61: 8 | F61: 6
A62: 11220 | B62: Urbanizaciones exentas y/o ajardinadas | C62: 24 | D62: 14 | E62: 8 | F62: 6
A63: 12100 | B63: Zonas industriales y comerciales | C63: 6 | D63: 4 | E63: 3 | F63: 3
A64: 12100 | B64: Granjas agrícolas | C64: 24 | D64: 14 | E64: 8 | F64: 6
A65: 12110 | B65: Zonas industriales | C65: 12 | D65: 7 | E65: 5 | F65: 4
A66: 12120 | B66: Grandes superficies de equipamiento y servicios | C66: 6 | D66: 4 | E66: 3 | F66: 3
A67: 12200 | B67: Redes viarias, ferroviarias y terrenos asociados | C67: 1 | D67: 1 | E67: 1 | F67: 1 | G67: =+E67 -> 1 | H67: G.2
A68: 12210 | B68: Autopistas, autovías y terrenos asociados | C68: 1 | D68: 1 | E68: 1 | F68: 1
A69: 12220 | B69: Complejos ferroviarios | C69: 12 | D69: 7 | E69: 5 | F69: 4
A70: 12300 | B70: Zonas portuarias | C70: 1 | D70: 1 | E70: 1 | F70: 1
A71: 12400 | B71: Aeropuertos | C71: 24 | D71: 14 | E71: 8 | F71: 6
A72: 13100 | B72: Zonas de extracción minera | C72: 16 | D72: 9 | E72: 6 | F72: 5
...

Sheet Datos 2
T1: Actualizado al: | U1: =+'Calculo Hidrológico T 25 - (A)'!G1 -> 46079
B2: =+'Calculo Hidrológico T 25 - (A)'!B2 -> CALCULO HIDROLOGICO: Mejora Carretera Guadalmar; 535.2
C4: PERIODO DE RETORNO EN AÑOS (T)
B5: Cv | C5: 2 | D5: 5 | E5: 10 | F5: 25 | G5: 50 | H5: 100 | I5: 200 | J5: 500 | V5: P: maxima precipitación diaria anual | Y5: D.1
B6: 0.3 | C6: 0.935 | D6: 1.194 | E6: 1.377 | F6: 1.625 | G6: 1.823 | H6: 2.022 | I6: 2.251 | J6: 2.541 | V6: 68
B7: 0.31 | C7: 0.932 | D7: 1.198 | E7: 1.385 | F7: 1.64 | G7: 1.854 | H7: 2.068 | I7: 2.296 | J7: 2.602
B8: 0.32 | C8: 0.929 | D8: 1.202 | E8: 1.4 | F8: 1.671 | G8: 1.884 | H8: 2.098 | I8: 2.342 | J8: 2.663
B9: 0.33 | C9: 0.927 | D9: 1.209 | E9: 1.415 | F9: 1.686 | G9: 1.915 | H9: 2.144 | I9: 2.388 | J9: 2.724
B10: 0.34 | C10: 0.924 | D10: 1.213 | E10: 1.423 | F10: 1.717 | G10: 1.93 | H10: 2.174 | I10: 2.434 | J10: 2.785
B11: 0.35 | C11: 0.921 | D11: 1.217 | E11: 1.438 | F11: 1.732 | G11: 1.961 | H11: 2.22 | I11: 2.48 | J11: 2.831
B12: 0.36 | C12: 0.919 | D12: 1.225 | E12: 1.446 | F12: 1.747 | G12: 1.991 | H12: 2.251 | I12: 2.525 | J12: 2.892
B13: 0.37 | C13: 0.917 | D13: 1.232 | E13: 1.461 | F13: 1.778 | G13: 2.022 | H13: 2.281 | I13: 2.571 | J13: 2.953
B14: 0.38 | C14: 0.914 | D14: 1.24 | E14: 1.469 | F14: 1.793 | G14: 2.052 | H14: 2.327 | I14: 2.617 | J14: 3.014
B15: 0.39 | C15: 0.912 | D15: 1.243 | E15: 1.484 | F15: 1.808 | G15: 2.083 | H15: 2.357 | I15: 2.663 | J15: 3.067
B16: 0.4 | C16: 0.909 | D16: 1.247 | E16: 1.492 | F16: 1.839 | G16: 2.113 | H16: 2.403 | I16: 2.708 | J16: 3.128
B17: 0.41 | C17: 0.906 | D17: 1.255 | E17: 1.507 | F17: 1.854 | G17: 2.144 | H17: 2.434 | I17: 2.754 | J17: 3.189
B18: 0.42 | C18: 0.904 | D18: 1.259 | E18: 1.514 | F18: 1.884 | G18: 2.174 | H18: 2.48 | I18: 2.8 | J18: 3.25
... B23: 0.47 | C23: 0.892 | D23: 1.286 | E23: 1.579 | F23: 1.991 | G23: 2.312 | H23: 2.663 | I23: 3.044 | J23: 3.555
A24: D.2 | B24: 0.48 | C24: 0.89 | D24: 1.289 | E24: 1.595 | F24: 2.007 | G24: 2.342 | H24: 2.708 | I24: 3.098 | J24: 3.616
B25: 0.49 | C25: 0.887 | D25: 1.293 | E25: 1.603 | F25: 2.022 | G25: 2.373 | H25: 2.739 | I25: 3.128 | J25: 3.677
B26: 0.5 | C26: 0.885 | D26: 1.297 | E26: 1.61 | F26: 2.052 | G26: 2.403 | H26: 2.785 | I26: 3.189 | J26: 3.738
B27: 0.51 | C27: 0.883 | D27: 1.301 | E27: 1.625 | F27: 2.068 | G27: 2.434 | H27: 2.815 | I27: 3.22 | J27: 3.799
B28: 0.52 | C28: 0.881 | D28: 1.308 | E28: 1.64 | F28: 2.098 | G28: 2.464 | H28: 2.861 | I28: 3.281 | J28: 3.86
M33: G.8.1 | N33: G.8.2 | S33: G.8.3
L34: Región | M34: Valor medio βm | N34: Δ50% | O34: Δ67% | P34: Δ90% | Q34: T=2 | R34: T=5 | S34: T=25 | T34: T=100 | U34: T=500
L35: 11 | M35: 0.9 | N35: 0.2 | O35: 0.3 | P35: 0.5 | Q35: 0.8 | R35: 0.9 | S35: 1.13 | T35: 1.34 | U35: 1.59
L36: 12 | M36: 0.95 | N36: 0.2 | O36: 0.25 | P36: 0.45 | Q36: 0.75 | R36: 0.9 | S36: 1.14 | T36: 1.33 | U36: 1.56
L37: 13 | M37: 0.6 | N37: 0.15 | O37: 0.25 | P37: 0.4 | Q37: 0.74 | R37: 0.9 | S37: 1.15 | T37: 1.34 | U37: 1.55
L38: 21 | M38: 1.2 | N38: 0.2 | O38: 0.35 | P38: 0.55 | Q38: 0.74 | R38: 0.88 | S38: 1.18 | T38: 1.47 | U38: 1.9
L39: 22 | M39: 1.5 | N39: 0.15 | O39: 0.2 | P39: 0.35 | Q39: 0.74 | R39: 0.9 | S39: 1.12 | T39: 1.27 | U39: 1.37
L40: 23 | M40: 0.7 | N40: 0.2 | O40: 0.35 | P40: 0.55 | Q40: 0.77 | R40: 0.89 | S40: 1.15 | T40: 1.44 | U40: 1.82
L41: 24 | M41: 1.1 | N41: 0.15 | O41: 0.2 | P41: 0.35 | Q41: 0.76 | R41: 0.9 | S41: 1.14 | T41: 1.36 | U41: 1.63
L42: 25 | M42: 0.6 | N42: 0.15 | O42: 0.2 | P42: 0.35 | Q42: 0.82 | R42: 0.92 | S42: 1.12 | T42: 1.29 | U42: 1.48
L43: 31 | M43: 0.9 | N43: 0.2 | O43: 0.3 | P43: 0.5 | Q43: 0.87 | R43: 0.93 | S43: 1.1 | T43: 1.26 | U43: 1.45
L44: 32 | M44: 1 | N44: 0.2 | O44: 0.3 | P44: 0.5 | Q44: 0.82 | R44: 0.91 | S44: 1.12 | T44: 1.31 | U44: 1.54
L45: 33 | M45: 2.15 | N45: 0.25 | O45: 0.4 | P45: 0.65 | Q45: 0.7 | R45: 0.88 | S45: 1.15 | T45: 1.38 | U45: 1.62
L46: 41 | M46: 1.2 | N46: 0.2 | O46: 0.25 | P46: 0.45 | Q46: 0.91 | R46: 0.96 | S46: 1 | T46: 1 | U46: 1
... L53: 71 | M53: 1.2 | N53: 0.15 | O53: 0.2 | P53: 0.35 | Q53: 0.82 | R53: 0.94 | S53: 1 | T53: 1 | U53: 1
L54: 72 | M54: 2.1 | N54: 0.3 | O54: 0.45 | P54: 0.7 | Q54: 0.67 | R54: 0.86 | S54: 1 | T54: - | U54: -
L55: 81 | M55: 1.3 | N55: 0.25 | O55: 0.35 | P55: 0.6 | Q55: 0.76 | R55: 0.9 | S55: 1.14 | T55: 1.34 | U55: 1.58
...

Sheet SITUACIÓN
B2: =+'[1]Calculo Hidrológico T 25 - (A)'!B2 -> CALCULO HIDROLOGICO: Mejora Carretera Guadalmar; 535.2 | K2: SITUACIÓN
